<?xml version="1.0" encoding="utf-8"?>
<!-- =================================================================================== -->
<!-- |    This document was autogenerated by xacro from /home/wgieruls/velma/ws_velma_os/src/velma_robot/velma_description/robots/velma.urdf.xacro | -->
<!-- |    EDITING THIS FILE BY HAND IS NOT RECOMMENDED                                 | -->
<!-- =================================================================================== -->
<robot name="velma" xmlns:controller="http://playerstage.sourceforge.net/gazebo/xmlschema/#controller" xmlns:geom="http://playerstage.sourceforge.net/gazebo/xmlschema/#geom" xmlns:interface="http://playerstage.sourceforge.net/gazebo/xmlschema/#interface" xmlns:sensor="http://playerstage.sourceforge.net/gazebo/xmlschema/#sensor">
  <material name="DarkGrey">
    <color rgba="0.3 0.3 0.3 1.0"/>
  </material>
  <material name="Red">
    <color rgba="0.3 0.3 0.3 1.0"/>
  </material>
  <material name="Black">
    <color rgba="0 0 0 1.0"/>
  </material>
  <material name="Orange">
    <color rgba="1.0 0.487 0 1.0"/>
  </material>
  <material name="Silver">
    <color rgba="1.0 1.0 1.0 1.0"/>
  </material>
  <material name="Grey">
    <color rgba="0.7 0.7 0.7 1.0"/>
  </material>
  <material name="Blue">
    <color rgba="0.0 0.0 0.8 1.0"/>
  </material>
  <material name="HandGray">
    <color rgba="0.953 0.996 0.694 1.0"/>
  </material>
  <material name="SickBlue">
    <color rgba="0.3058 0.5921 0.7294 1.0"/>
  </material>
  <!-- torso_link2_left_arm_base_joint -->
  <!--
     These are the old calibration parameters
<xacro:property name="cal_torso_link2_left_arm_base_joint_x" value="0.0" />
<xacro:property name="cal_torso_link2_left_arm_base_joint_y" value="0.000188676" />
<xacro:property name="cal_torso_link2_left_arm_base_joint_z" value="1.17335" />
<xacro:property name="cal_torso_link2_left_arm_base_joint_roll" value="0" />
-->
  <material name="bh_DarkGrey">
    <color rgba="0.3 0.3 0.3 1.0"/>
  </material>
  <material name="bh_Red">
    <color rgba="0.3 0.3 0.3 1.0"/>
  </material>
  <material name="bh_Black">
    <color rgba="0 0 0 1.0"/>
  </material>
  <material name="bh_Orange">
    <color rgba="1.0 0.487 0 1.0"/>
  </material>
  <material name="bh_Silver">
    <color rgba="1.0 1.0 1.0 1.0"/>
  </material>
  <material name="bh_Grey">
    <color rgba="0.7 0.7 0.7 1.0"/>
  </material>
  <material name="bh_Blue">
    <color rgba="0.0 0.0 0.8 1.0"/>
  </material>
  <material name="bh_HandGrey">
    <color rgba="0.953 0.996 0.694 1.0"/>
  </material>
  <material name="bh_SickBlue">
    <color rgba="0.3058 0.5921 0.7294 1.0"/>
  </material>
  <!-- Gazebo Plugin -->
  <gazebo>
    <plugin filename="librtt_gazebo_deployer.so" name="rtt_gazebo">
      <isolated/>
      <collision_detector>fcl</collision_detector>
      <master_service>
        <name>velma_sim_gazebo</name>
        <subname>velma_sim_gazebo</subname>
      </master_service>
      <component>
        <package>velma_sim_gazebo</package>
        <type>TorsoGazebo</type>
        <name>TorsoSim</name>
      </component>
      <component>
        <package>velma_sim_gazebo</package>
        <type>LWRGazebo</type>
        <name>LWRrSim</name>
      </component>
      <component>
        <package>velma_sim_gazebo</package>
        <type>LWRGazebo</type>
        <name>LWRlSim</name>
      </component>
      <component>
        <package>velma_sim_gazebo</package>
        <type>FtSensorGazebo</type>
        <name>LeftFtSensor</name>
      </component>
      <component>
        <package>velma_sim_gazebo</package>
        <type>FtSensorGazebo</type>
        <name>RightFtSensor</name>
      </component>
      <component>
        <package>velma_sim_gazebo</package>
        <type>BarrettHandGazebo</type>
        <name>RightHand</name>
      </component>
      <component>
        <package>velma_sim_gazebo</package>
        <type>BarrettTactileGazebo</type>
        <name>RightHandTactile</name>
      </component>
      <component>
        <package>velma_sim_gazebo</package>
        <type>OptoforceGazebo</type>
        <name>RightHandOptoforce</name>
      </component>
      <component>
        <package>velma_sim_gazebo</package>
        <type>BarrettHandGazebo</type>
        <name>LeftHand</name>
      </component>
      <component>
        <package>velma_sim_gazebo</package>
        <type>BarrettTactileGazebo</type>
        <name>LeftHandTactile</name>
      </component>
      <component>
        <package>velma_sim_gazebo</package>
        <type>OptoforceGazebo</type>
        <name>LeftHandOptoforce</name>
      </component>
    </plugin>
  </gazebo>
  <link name="world"/>
  <joint name="torso_base_joint" type="fixed">
    <origin rpy="0 0 0" xyz="0 0 0"/>
    <parent link="world"/>
    <child link="torso_base"/>
  </joint>
  <link name="torso_base">
    <!--
      <visual>
        <origin xyz="0 0 0.1" rpy="0.0 0 0" />
        <geometry>
          <mesh filename="package://velma_description/meshes/torso_base.STL" />
        </geometry>
        <material name="torso_base">
          <color rgba="0.3 0.3 0.3 1"/>
        </material>
      </visual>
    -->
    <visual>
      <origin rpy="0 0 0" xyz="0 0 0.1"/>
      <geometry>
        <box size="0.7 0.8 0.2"/>
      </geometry>
      <material name="torso_base">
        <color rgba="0.3 0.3 0.3 1"/>
      </material>
    </visual>
    <visual>
      <origin rpy="0 0 0" xyz="0 0 0.26"/>
      <geometry>
        <box size="0.4 0.4 0.12"/>
      </geometry>
      <material name="torso_base">
        <color rgba="0.3 0.3 0.3 1"/>
      </material>
    </visual>
    <collision>
      <origin rpy="0 0 0" xyz="0 0 0.1"/>
      <geometry>
        <box size="0.7 0.8 0.2"/>
      </geometry>
    </collision>
    <collision>
      <origin rpy="0 0 0" xyz="0 0 0.26"/>
      <geometry>
        <box size="0.4 0.4 0.12"/>
      </geometry>
    </collision>
    <!--
      <collision>
        <origin xyz="0 0 0.1" rpy="0 0 0"/>
        <geometry>
          <mesh filename="package://velma_description/meshes/collision/torso_base_collision.STL" />
        </geometry>
      </collision>
-->
    <!--
      <self_collision_checking>
        <origin xyz="-0.2 0.0 0.6" rpy="1.57075 0 0"/>
        <geometry>
          <capsule radius="0.20" length="0.9"/>
        </geometry>
      </self_collision_checking>
-->
    <inertial>
      <mass value="30.0"/>
      <origin rpy="0 0 0" xyz="0 -0.06 0.130"/>
      <inertia ixx="0.9" ixy="0" ixz="0" iyy="0.9" iyz="0" izz="1.35"/>
    </inertial>
  </link>
  <gazebo reference="torso_base">
    <turnGravityOff>false</turnGravityOff>
    <selfCollide>true</selfCollide>
    <material>Gazebo/DarkGrey</material>
  </gazebo>
  <!--
      Changed joint origin from 0.1 to 0.03 (moved 7cm down) to make it similar to the real robot.
      head_base - real height: 1.34
      in urdf (with joint origin at 0.1): 1.41
    -->
  <joint name="torso_0_joint" type="revolute">
    <origin rpy="0 0 0" xyz="0 0 0.03"/>
    <axis xyz="0 0 1"/>
    <limit effort="100" lower="-1.57" upper="1.57" velocity="100"/>
    <parent link="torso_base"/>
    <child link="torso_link0"/>
    <dynamics damping="10.0"/>
  </joint>
  <link name="torso_link0">
    <visual>
      <origin rpy="0 0 0" xyz="0 0 0.52"/>
      <geometry>
        <mesh filename="package://velma_description/meshes/collision/torso0_collision.stl"/>
      </geometry>
      <material name="torso_base">
        <color rgba="0.7 0.7 0.7 1"/>
      </material>
    </visual>
    <collision>
      <origin rpy="0 0 0" xyz="0 0 0.52"/>
      <geometry>
        <mesh filename="package://velma_description/meshes/collision/torso0_collision.stl"/>
      </geometry>
    </collision>
    <self_collision_checking>
      <origin rpy="0 0 0" xyz="0 0.0 0.8"/>
      <geometry>
        <capsule length="1.0" radius="0.20"/>
      </geometry>
    </self_collision_checking>
    <self_collision_checking>
      <origin rpy="0 0 0" xyz="-0.1 0.0 0.45"/>
      <geometry>
        <capsule length="0.4" radius="0.18"/>
      </geometry>
    </self_collision_checking>
    <inertial>
      <mass value="30.0"/>
      <origin rpy="0 0 0" xyz="0 -0.06 0.130"/>
      <inertia ixx="3.175" ixy="0" ixz="0" iyy="3.175" iyz="0" izz="1.35"/>
    </inertial>
  </link>
  <gazebo reference="torso_link0">
    <turnGravityOff>false</turnGravityOff>
    <selfCollide>true</selfCollide>
    <material>Gazebo/DarkGrey</material>
  </gazebo>
  <joint name="torso_link0_right_arm_base_joint" type="fixed">
    <origin rpy="-0.000449354954172 -1.04747154567 1.57047094956" xyz="-0.0004 -0.000888676 1.17335"/>
    <parent link="torso_link0"/>
    <child link="calib_right_arm_base_link"/>
  </joint>
  <link name="calib_right_arm_base_link">
    <inertial>
      <mass value="2.0"/>
      <origin xyz="0 0 0.055"/>
      <inertia ixx="0.00381666666667" ixy="0" ixz="0" iyy="0.0036" iyz="0" izz="0.00381666666667"/>
    </inertial>
    <visual>
      <origin rpy="0 0 0" xyz="0 0 0"/>
      <geometry>
        <mesh filename="package://lwr_defs/meshes/lwr/base_simplified.STL"/>
      </geometry>
      <material name="Orange">
        <color rgba="1 0.5 0 1.0"/>
      </material>
    </visual>
    <collision>
      <origin rpy="0 0 3.14159265359" xyz="0 0 0.055"/>
      <geometry>
        <mesh filename="package://lwr_defs/meshes/lwr/convex/arm_base_convex.stl"/>
      </geometry>
    </collision>
    <self_collision_checking>
      <origin rpy="0 0 3.14159265359" xyz="0 0 0.055"/>
      <geometry>
        <capsule length="0.11" radius="0.07"/>
      </geometry>
    </self_collision_checking>
  </link>
  <joint name="right_arm_0_joint" type="revolute">
    <origin rpy="0 0 0" xyz="0 0 0.11"/>
    <axis xyz="0 0 1"/>
    <limit effort="204" lower="-2.96705972839" upper="2.96705972839" velocity="1.91986217719"/>
    <dynamics damping="1.0"/>
    <parent link="calib_right_arm_base_link"/>
    <child link="right_arm_1_link"/>
  </joint>
  <link name="right_arm_1_link">
    <inertial>
      <mass value="2.0"/>
      <origin rpy="0 0 0" xyz="0 -0.06 0.13"/>
      <inertia ixx="0.0136666666667" ixy="0" ixz="0" iyy="0.003" iyz="0" izz="0.0118666666667"/>
    </inertial>
    <visual>
      <origin rpy="0 0 0" xyz="0 0 -0.008"/>
      <geometry>
        <mesh filename="package://lwr_defs/meshes/lwr/link_1_simplified.STL"/>
      </geometry>
      <material name="Orange">
        <color rgba="1 0.5 0 1.0"/>
      </material>
    </visual>
    <collision>
      <origin rpy="0 0 0" xyz="0 0 0"/>
      <geometry>
        <mesh filename="package://lwr_defs/meshes/lwr/convex/arm_segment_a_convex.stl"/>
      </geometry>
    </collision>
    <self_collision_checking>
      <origin rpy="0.2 0 0" xyz="0 -0.015 0.1"/>
      <geometry>
        <capsule length="0.208" radius="0.065"/>
      </geometry>
    </self_collision_checking>
  </link>
  <joint name="right_arm_1_joint" type="revolute">
    <origin rpy="0 0 0" xyz="0 0 0.2005"/>
    <axis xyz="0 1 0"/>
    <limit effort="306" lower="-2.09439510239" upper="2.09439510239" velocity="1.91986217719"/>
    <dynamics damping="1.0"/>
    <parent link="right_arm_1_link"/>
    <child link="right_arm_2_link"/>
  </joint>
  <link name="right_arm_2_link">
    <inertial>
      <mass value="2.0"/>
      <origin rpy="0 0 0" xyz="0 0.06 0.07"/>
      <inertia ixx="0.0136666666667" ixy="0" ixz="0" iyy="0.003" iyz="0" izz="0.0118666666667"/>
    </inertial>
    <visual>
      <origin rpy="0 0 0" xyz="0 0 0.0"/>
      <geometry>
        <mesh filename="package://lwr_defs/meshes/lwr/link_2_simplified.STL"/>
      </geometry>
      <material name="Orange">
        <color rgba="1 0.5 0 1.0"/>
      </material>
    </visual>
    <collision>
      <origin rpy="3.14159265359 0 0" xyz="0 0 0.2"/>
      <geometry>
        <mesh filename="package://lwr_defs/meshes/lwr/convex/arm_segment_b_convex.stl"/>
      </geometry>
    </collision>
    <self_collision_checking>
      <origin rpy="0.200 0 0" xyz="0 0.015 0.1"/>
      <geometry>
        <capsule length="0.208" radius="0.065"/>
      </geometry>
    </self_collision_checking>
  </link>
  <joint name="right_arm_2_joint" type="revolute">
    <origin rpy="0 0 0" xyz="0 0 0.20"/>
    <axis xyz="0 0 1"/>
    <limit effort="204" lower="-2.96705972839" upper="2.96705972839" velocity="2.26892802759"/>
    <dynamics damping="1.0"/>
    <parent link="right_arm_2_link"/>
    <child link="right_arm_3_link"/>
  </joint>
  <link name="right_arm_3_link">
    <inertial>
      <mass value="2.0"/>
      <origin rpy="0 0 0" xyz="0 0.06 0.13"/>
      <inertia ixx="0.0136666666667" ixy="0" ixz="0" iyy="0.003" iyz="0" izz="0.0118666666667"/>
    </inertial>
    <visual>
      <origin rpy="0 0 0" xyz="0 0 -0.008"/>
      <geometry>
        <mesh filename="package://lwr_defs/meshes/lwr/link_3_simplified.STL"/>
      </geometry>
      <material name="Orange">
        <color rgba="1 0.5 0 1.0"/>
      </material>
    </visual>
    <collision>
      <origin rpy="0 0 3.14159265359" xyz="0 0 0"/>
      <geometry>
        <mesh filename="package://lwr_defs/meshes/lwr/convex/arm_segment_a_convex.stl"/>
      </geometry>
    </collision>
    <self_collision_checking>
      <origin rpy="-0.2 0 0" xyz="0 0.015 0.1"/>
      <geometry>
        <capsule length="0.208" radius="0.065"/>
      </geometry>
    </self_collision_checking>
  </link>
  <joint name="right_arm_3_joint" type="revolute">
    <origin rpy="0 0 0" xyz="0 0 0.20"/>
    <axis xyz="0 -1 0"/>
    <limit effort="306" lower="-2.09439510239" upper="2.09439510239" velocity="2.26892802759"/>
    <dynamics damping="1.0"/>
    <parent link="right_arm_3_link"/>
    <child link="right_arm_4_link"/>
  </joint>
  <link name="right_arm_4_link">
    <inertial>
      <mass value="2.0"/>
      <origin rpy="0 0 0" xyz="0 -0.06 0.07"/>
      <inertia ixx="0.0136666666667" ixy="0" ixz="0" iyy="0.003" iyz="0" izz="0.0118666666667"/>
    </inertial>
    <visual>
      <origin rpy="0 0 0" xyz="0 0 0.0"/>
      <geometry>
        <mesh filename="package://lwr_defs/meshes/lwr/link_4_simplified.STL"/>
      </geometry>
      <material name="Orange">
        <color rgba="1 0.5 0 1.0"/>
      </material>
    </visual>
    <collision>
      <origin rpy="0 3.14159265359 0" xyz="0 0 0.2"/>
      <geometry>
        <mesh filename="package://lwr_defs/meshes/lwr/convex/arm_segment_b_convex.stl"/>
      </geometry>
    </collision>
    <self_collision_checking>
      <origin rpy="-0.2 0 0" xyz="0 -0.015 0.1"/>
      <geometry>
        <capsule length="0.208" radius="0.065"/>
      </geometry>
    </self_collision_checking>
  </link>
  <joint name="right_arm_4_joint" type="revolute">
    <origin rpy="0 0 0" xyz="0 0 0.20"/>
    <axis xyz="0 0 1"/>
    <limit effort="204" lower="-2.96705972839" upper="2.96705972839" velocity="2.26892802759"/>
    <dynamics damping="1.0"/>
    <parent link="right_arm_4_link"/>
    <child link="right_arm_5_link"/>
  </joint>
  <link name="right_arm_5_link">
    <inertial>
      <mass value="2.0"/>
      <origin rpy="0 0 0" xyz="0 0 0.124"/>
      <inertia ixx="0.0126506666667" ixy="0" ixz="0" iyy="0.003" iyz="0" izz="0.0108506666667"/>
    </inertial>
    <visual>
      <origin rpy="0 0 0" xyz="0 0 -0.008"/>
      <geometry name="right_arm_5_geom">
        <mesh filename="package://lwr_defs/meshes/lwr/link_5_simplified.STL"/>
      </geometry>
      <material name="Green">
        <color rgba="1 0.5 0 1.0"/>
      </material>
    </visual>
    <visual>
      <origin rpy="0 0 0" xyz="0 0 -0.008"/>
      <geometry name="right_arm_5_geom">
        <mesh filename="package://lwr_defs/meshes/lwr/link_5_simplified.STL"/>
      </geometry>
      <material name="Blue">
        <color rgba="1 0.5 0 1.0"/>
      </material>
    </visual>
    <collision>
      <origin rpy="0 0 0" xyz="0 0 0"/>
      <geometry>
        <mesh filename="package://lwr_defs/meshes/lwr/convex/arm_segment_last_convex.stl"/>
      </geometry>
    </collision>
    <self_collision_checking>
      <origin rpy="0.207 0 0" xyz="0 -0.015 0.095"/>
      <geometry>
        <capsule length="0.198" radius="0.065"/>
      </geometry>
    </self_collision_checking>
  </link>
  <joint name="right_arm_5_joint" type="revolute">
    <origin rpy="0 0 0" xyz="0 0 0.19"/>
    <axis xyz="0 1 0"/>
    <limit effort="306" lower="-2.09439510239" upper="2.09439510239" velocity="3.14159265359"/>
    <dynamics damping="1.0"/>
    <parent link="right_arm_5_link"/>
    <child link="right_arm_6_link"/>
  </joint>
  <link name="right_arm_6_link">
    <inertial>
      <mass value="0.2"/>
      <origin rpy="0 0 0" xyz="0 0 0.0625"/>
      <inertia ixx="0.000520833333333" ixy="0" ixz="0" iyy="0.000520833333333" iyz="0" izz="0.000520833333333"/>
    </inertial>
    <visual>
      <origin rpy="0 0 0" xyz="0 0 0"/>
      <geometry>
        <mesh filename="package://lwr_defs/meshes/lwr/link_6_simplified.STL"/>
      </geometry>
      <material name="Grey">
        <color rgba="0.65 0.65 0.65 1.0"/>
      </material>
    </visual>
    <collision>
      <origin rpy="0 0 0" xyz="0 0 0"/>
      <geometry>
        <mesh filename="package://lwr_defs/meshes/lwr/convex/arm_wrist_convex.stl"/>
      </geometry>
    </collision>
    <self_collision_checking>
      <origin rpy="0 0 0" xyz="0 0.01 0"/>
      <geometry>
        <capsule length="0" radius="0.08"/>
      </geometry>
    </self_collision_checking>
  </link>
  <joint name="right_arm_6_joint" type="revolute">
    <origin rpy="0 0 0" xyz="0 0 0.078"/>
    <axis xyz="0 0 1"/>
    <limit effort="204" lower="-2.96705972839" upper="2.96705972839" velocity="3.14159265359"/>
    <dynamics damping="1.0"/>
    <parent link="right_arm_6_link"/>
    <child link="right_arm_7_link"/>
  </joint>
  <link name="right_arm_7_link">
    <inertial>
      <mass value="0.002"/>
      <origin xyz="0 0 0"/>
      <inertia ixx="0.000333333333333" ixy="0" ixz="0" iyy="0.000333333333333" iyz="0" izz="0.000333333333333"/>
    </inertial>
    <visual>
      <origin rpy="0 0 0" xyz="0 0 0"/>
      <geometry>
        <mesh filename="package://lwr_defs/meshes/lwr/link_7_simplified.STL"/>
      </geometry>
      <material name="Grey">
        <color rgba="0.65 0.65 0.65 1.0"/>
      </material>
    </visual>
  </link>
  <joint name="right_arm_ee_joint" type="fixed">
    <origin rpy="0 0 0" xyz="0 0 0"/>
    <parent link="right_arm_7_link"/>
    <child link="right_arm_ee_link"/>
  </joint>
  <link name="right_arm_ee_link">
    <inertial>
      <mass value="0"/>
      <origin rpy="0 0 0" xyz="0 0 0"/>
      <inertia ixx="0" ixy="0" ixz="0" iyy="0" iyz="0" izz="0"/>
    </inertial>
  </link>
  <gazebo reference="calib_right_arm_base_link">
    <turnGravityOff>false</turnGravityOff>
    <selfCollide>true</selfCollide>
    <material>Gazebo/Orange</material>
  </gazebo>
  <gazebo reference="right_arm_1_link">
    <turnGravityOff>false</turnGravityOff>
    <selfCollide>true</selfCollide>
    <material>Gazebo/Orange</material>
  </gazebo>
  <gazebo reference="right_arm_2_link">
    <turnGravityOff>false</turnGravityOff>
    <selfCollide>true</selfCollide>
    <material>Gazebo/Orange</material>
  </gazebo>
  <gazebo reference="right_arm_3_link">
    <turnGravityOff>false</turnGravityOff>
    <selfCollide>true</selfCollide>
    <material>Gazebo/Orange</material>
  </gazebo>
  <gazebo reference="right_arm_4_link">
    <turnGravityOff>false</turnGravityOff>
    <selfCollide>true</selfCollide>
    <material>Gazebo/Orange</material>
  </gazebo>
  <gazebo reference="right_arm_5_link">
    <turnGravityOff>false</turnGravityOff>
    <selfCollide>true</selfCollide>
    <material>Gazebo/Orange</material>
  </gazebo>
  <gazebo reference="right_arm_6_link">
    <turnGravityOff>false</turnGravityOff>
    <selfCollide>true</selfCollide>
    <material>Gazebo/Grey</material>
  </gazebo>
  <gazebo reference="right_arm_6_joint">
    <provideFeedback>true</provideFeedback>
  </gazebo>
  <gazebo reference="right_arm_7_link">
    <turnGravityOff>false</turnGravityOff>
    <selfCollide>true</selfCollide>
    <material>Gazebo/Grey</material>
  </gazebo>
  <!--
    <transmission name="${name}_arm_0_trans" type="SimpleTransmission">
      <actuator name="${name}_arm_0_motor" />
      <joint name="${name}_arm_0_joint" />
      <mechanicalReduction>1.0</mechanicalReduction>
    </transmission>
    <transmission name="${name}_arm_1_trans" type="SimpleTransmission">
      <actuator name="${name}_arm_1_motor" />
      <joint name="${name}_arm_1_joint" />
      <mechanicalReduction>1.0</mechanicalReduction>
    </transmission>
    <transmission name="${name}_arm_2_trans" type="SimpleTransmission">
      <actuator name="${name}_arm_2_motor" />
      <joint name="${name}_arm_2_joint" />
      <mechanicalReduction>1.0</mechanicalReduction>
    </transmission>
    <transmission name="${name}_arm_3_trans" type="SimpleTransmission">
      <actuator name="${name}_arm_3_motor" />
      <joint name="${name}_arm_3_joint" />
      <mechanicalReduction>1.0</mechanicalReduction>
    </transmission>
    <transmission name="${name}_arm_4_trans" type="SimpleTransmission">
      <actuator name="${name}_arm_4_motor" />
      <joint name="${name}_arm_4_joint" />
      <mechanicalReduction>1.0</mechanicalReduction>
    </transmission>
    <transmission name="${name}_arm_5_trans" type="SimpleTransmission">
      <actuator name="${name}_arm_5_motor" />
      <joint name="${name}_arm_5_joint" />
      <mechanicalReduction>1.0</mechanicalReduction>
    </transmission>
    <transmission name="${name}_arm_6_trans" type="SimpleTransmission">
      <actuator name="${name}_arm_6_motor" />
      <joint name="${name}_arm_6_joint" />
      <mechanicalReduction>1.0</mechanicalReduction>
    </transmission>
  -->
  <joint name="torso_link0_left_arm_base_joint" type="fixed">
    <origin rpy="0.000870134249967 1.04750488979 1.57242548265" xyz="-0.0006 -0.001311324 1.17335"/>
    <parent link="torso_link0"/>
    <child link="calib_left_arm_base_link"/>
  </joint>
  <link name="calib_left_arm_base_link">
    <inertial>
      <mass value="2.0"/>
      <origin xyz="0 0 0.055"/>
      <inertia ixx="0.00381666666667" ixy="0" ixz="0" iyy="0.0036" iyz="0" izz="0.00381666666667"/>
    </inertial>
    <visual>
      <origin rpy="0 0 0" xyz="0 0 0"/>
      <geometry>
        <mesh filename="package://lwr_defs/meshes/lwr/base_simplified.STL"/>
      </geometry>
      <material name="Orange">
        <color rgba="1 0.5 0 1.0"/>
      </material>
    </visual>
    <collision>
      <origin rpy="0 0 3.14159265359" xyz="0 0 0.055"/>
      <geometry>
        <mesh filename="package://lwr_defs/meshes/lwr/convex/arm_base_convex.stl"/>
      </geometry>
    </collision>
    <self_collision_checking>
      <origin rpy="0 0 3.14159265359" xyz="0 0 0.055"/>
      <geometry>
        <capsule length="0.11" radius="0.07"/>
      </geometry>
    </self_collision_checking>
  </link>
  <joint name="left_arm_0_joint" type="revolute">
    <origin rpy="0 0 0" xyz="0 0 0.11"/>
    <axis xyz="0 0 1"/>
    <limit effort="204" lower="-2.96705972839" upper="2.96705972839" velocity="1.91986217719"/>
    <dynamics damping="1.0"/>
    <parent link="calib_left_arm_base_link"/>
    <child link="left_arm_1_link"/>
  </joint>
  <link name="left_arm_1_link">
    <inertial>
      <mass value="2.0"/>
      <origin rpy="0 0 0" xyz="0 -0.06 0.13"/>
      <inertia ixx="0.0136666666667" ixy="0" ixz="0" iyy="0.003" iyz="0" izz="0.0118666666667"/>
    </inertial>
    <visual>
      <origin rpy="0 0 0" xyz="0 0 -0.008"/>
      <geometry>
        <mesh filename="package://lwr_defs/meshes/lwr/link_1_simplified.STL"/>
      </geometry>
      <material name="Orange">
        <color rgba="1 0.5 0 1.0"/>
      </material>
    </visual>
    <collision>
      <origin rpy="0 0 0" xyz="0 0 0"/>
      <geometry>
        <mesh filename="package://lwr_defs/meshes/lwr/convex/arm_segment_a_convex.stl"/>
      </geometry>
    </collision>
    <self_collision_checking>
      <origin rpy="0.2 0 0" xyz="0 -0.015 0.1"/>
      <geometry>
        <capsule length="0.208" radius="0.065"/>
      </geometry>
    </self_collision_checking>
  </link>
  <joint name="left_arm_1_joint" type="revolute">
    <origin rpy="0 0 0" xyz="0 0 0.2005"/>
    <axis xyz="0 1 0"/>
    <limit effort="306" lower="-2.09439510239" upper="2.09439510239" velocity="1.91986217719"/>
    <dynamics damping="1.0"/>
    <parent link="left_arm_1_link"/>
    <child link="left_arm_2_link"/>
  </joint>
  <link name="left_arm_2_link">
    <inertial>
      <mass value="2.0"/>
      <origin rpy="0 0 0" xyz="0 0.06 0.07"/>
      <inertia ixx="0.0136666666667" ixy="0" ixz="0" iyy="0.003" iyz="0" izz="0.0118666666667"/>
    </inertial>
    <visual>
      <origin rpy="0 0 0" xyz="0 0 0.0"/>
      <geometry>
        <mesh filename="package://lwr_defs/meshes/lwr/link_2_simplified.STL"/>
      </geometry>
      <material name="Orange">
        <color rgba="1 0.5 0 1.0"/>
      </material>
    </visual>
    <collision>
      <origin rpy="3.14159265359 0 0" xyz="0 0 0.2"/>
      <geometry>
        <mesh filename="package://lwr_defs/meshes/lwr/convex/arm_segment_b_convex.stl"/>
      </geometry>
    </collision>
    <self_collision_checking>
      <origin rpy="0.200 0 0" xyz="0 0.015 0.1"/>
      <geometry>
        <capsule length="0.208" radius="0.065"/>
      </geometry>
    </self_collision_checking>
  </link>
  <joint name="left_arm_2_joint" type="revolute">
    <origin rpy="0 0 0" xyz="0 0 0.20"/>
    <axis xyz="0 0 1"/>
    <limit effort="204" lower="-2.96705972839" upper="2.96705972839" velocity="2.26892802759"/>
    <dynamics damping="1.0"/>
    <parent link="left_arm_2_link"/>
    <child link="left_arm_3_link"/>
  </joint>
  <link name="left_arm_3_link">
    <inertial>
      <mass value="2.0"/>
      <origin rpy="0 0 0" xyz="0 0.06 0.13"/>
      <inertia ixx="0.0136666666667" ixy="0" ixz="0" iyy="0.003" iyz="0" izz="0.0118666666667"/>
    </inertial>
    <visual>
      <origin rpy="0 0 0" xyz="0 0 -0.008"/>
      <geometry>
        <mesh filename="package://lwr_defs/meshes/lwr/link_3_simplified.STL"/>
      </geometry>
      <material name="Orange">
        <color rgba="1 0.5 0 1.0"/>
      </material>
    </visual>
    <collision>
      <origin rpy="0 0 3.14159265359" xyz="0 0 0"/>
      <geometry>
        <mesh filename="package://lwr_defs/meshes/lwr/convex/arm_segment_a_convex.stl"/>
      </geometry>
    </collision>
    <self_collision_checking>
      <origin rpy="-0.2 0 0" xyz="0 0.015 0.1"/>
      <geometry>
        <capsule length="0.208" radius="0.065"/>
      </geometry>
    </self_collision_checking>
  </link>
  <joint name="left_arm_3_joint" type="revolute">
    <origin rpy="0 0 0" xyz="0 0 0.20"/>
    <axis xyz="0 -1 0"/>
    <limit effort="306" lower="-2.09439510239" upper="2.09439510239" velocity="2.26892802759"/>
    <dynamics damping="1.0"/>
    <parent link="left_arm_3_link"/>
    <child link="left_arm_4_link"/>
  </joint>
  <link name="left_arm_4_link">
    <inertial>
      <mass value="2.0"/>
      <origin rpy="0 0 0" xyz="0 -0.06 0.07"/>
      <inertia ixx="0.0136666666667" ixy="0" ixz="0" iyy="0.003" iyz="0" izz="0.0118666666667"/>
    </inertial>
    <visual>
      <origin rpy="0 0 0" xyz="0 0 0.0"/>
      <geometry>
        <mesh filename="package://lwr_defs/meshes/lwr/link_4_simplified.STL"/>
      </geometry>
      <material name="Orange">
        <color rgba="1 0.5 0 1.0"/>
      </material>
    </visual>
    <collision>
      <origin rpy="0 3.14159265359 0" xyz="0 0 0.2"/>
      <geometry>
        <mesh filename="package://lwr_defs/meshes/lwr/convex/arm_segment_b_convex.stl"/>
      </geometry>
    </collision>
    <self_collision_checking>
      <origin rpy="-0.2 0 0" xyz="0 -0.015 0.1"/>
      <geometry>
        <capsule length="0.208" radius="0.065"/>
      </geometry>
    </self_collision_checking>
  </link>
  <joint name="left_arm_4_joint" type="revolute">
    <origin rpy="0 0 0" xyz="0 0 0.20"/>
    <axis xyz="0 0 1"/>
    <limit effort="204" lower="-2.96705972839" upper="2.96705972839" velocity="2.26892802759"/>
    <dynamics damping="1.0"/>
    <parent link="left_arm_4_link"/>
    <child link="left_arm_5_link"/>
  </joint>
  <link name="left_arm_5_link">
    <inertial>
      <mass value="2.0"/>
      <origin rpy="0 0 0" xyz="0 0 0.124"/>
      <inertia ixx="0.0126506666667" ixy="0" ixz="0" iyy="0.003" iyz="0" izz="0.0108506666667"/>
    </inertial>
    <visual>
      <origin rpy="0 0 0" xyz="0 0 -0.008"/>
      <geometry name="left_arm_5_geom">
        <mesh filename="package://lwr_defs/meshes/lwr/link_5_simplified.STL"/>
      </geometry>
      <material name="Green">
        <color rgba="1 0.5 0 1.0"/>
      </material>
    </visual>
    <visual>
      <origin rpy="0 0 0" xyz="0 0 -0.008"/>
      <geometry name="left_arm_5_geom">
        <mesh filename="package://lwr_defs/meshes/lwr/link_5_simplified.STL"/>
      </geometry>
      <material name="Blue">
        <color rgba="1 0.5 0 1.0"/>
      </material>
    </visual>
    <collision>
      <origin rpy="0 0 0" xyz="0 0 0"/>
      <geometry>
        <mesh filename="package://lwr_defs/meshes/lwr/convex/arm_segment_last_convex.stl"/>
      </geometry>
    </collision>
    <self_collision_checking>
      <origin rpy="0.207 0 0" xyz="0 -0.015 0.095"/>
      <geometry>
        <capsule length="0.198" radius="0.065"/>
      </geometry>
    </self_collision_checking>
  </link>
  <joint name="left_arm_5_joint" type="revolute">
    <origin rpy="0 0 0" xyz="0 0 0.19"/>
    <axis xyz="0 1 0"/>
    <limit effort="306" lower="-2.09439510239" upper="2.09439510239" velocity="3.14159265359"/>
    <dynamics damping="1.0"/>
    <parent link="left_arm_5_link"/>
    <child link="left_arm_6_link"/>
  </joint>
  <link name="left_arm_6_link">
    <inertial>
      <mass value="0.2"/>
      <origin rpy="0 0 0" xyz="0 0 0.0625"/>
      <inertia ixx="0.000520833333333" ixy="0" ixz="0" iyy="0.000520833333333" iyz="0" izz="0.000520833333333"/>
    </inertial>
    <visual>
      <origin rpy="0 0 0" xyz="0 0 0"/>
      <geometry>
        <mesh filename="package://lwr_defs/meshes/lwr/link_6_simplified.STL"/>
      </geometry>
      <material name="Grey">
        <color rgba="0.65 0.65 0.65 1.0"/>
      </material>
    </visual>
    <collision>
      <origin rpy="0 0 0" xyz="0 0 0"/>
      <geometry>
        <mesh filename="package://lwr_defs/meshes/lwr/convex/arm_wrist_convex.stl"/>
      </geometry>
    </collision>
    <self_collision_checking>
      <origin rpy="0 0 0" xyz="0 0.01 0"/>
      <geometry>
        <capsule length="0" radius="0.08"/>
      </geometry>
    </self_collision_checking>
  </link>
  <joint name="left_arm_6_joint" type="revolute">
    <origin rpy="0 0 0" xyz="0 0 0.078"/>
    <axis xyz="0 0 1"/>
    <limit effort="204" lower="-2.96705972839" upper="2.96705972839" velocity="3.14159265359"/>
    <dynamics damping="1.0"/>
    <parent link="left_arm_6_link"/>
    <child link="left_arm_7_link"/>
  </joint>
  <link name="left_arm_7_link">
    <inertial>
      <mass value="0.002"/>
      <origin xyz="0 0 0"/>
      <inertia ixx="0.000333333333333" ixy="0" ixz="0" iyy="0.000333333333333" iyz="0" izz="0.000333333333333"/>
    </inertial>
    <visual>
      <origin rpy="0 0 0" xyz="0 0 0"/>
      <geometry>
        <mesh filename="package://lwr_defs/meshes/lwr/link_7_simplified.STL"/>
      </geometry>
      <material name="Grey">
        <color rgba="0.65 0.65 0.65 1.0"/>
      </material>
    </visual>
  </link>
  <joint name="left_arm_ee_joint" type="fixed">
    <origin rpy="0 0 0" xyz="0 0 0"/>
    <parent link="left_arm_7_link"/>
    <child link="left_arm_ee_link"/>
  </joint>
  <link name="left_arm_ee_link">
    <inertial>
      <mass value="0"/>
      <origin rpy="0 0 0" xyz="0 0 0"/>
      <inertia ixx="0" ixy="0" ixz="0" iyy="0" iyz="0" izz="0"/>
    </inertial>
  </link>
  <gazebo reference="calib_left_arm_base_link">
    <turnGravityOff>false</turnGravityOff>
    <selfCollide>true</selfCollide>
    <material>Gazebo/Orange</material>
  </gazebo>
  <gazebo reference="left_arm_1_link">
    <turnGravityOff>false</turnGravityOff>
    <selfCollide>true</selfCollide>
    <material>Gazebo/Orange</material>
  </gazebo>
  <gazebo reference="left_arm_2_link">
    <turnGravityOff>false</turnGravityOff>
    <selfCollide>true</selfCollide>
    <material>Gazebo/Orange</material>
  </gazebo>
  <gazebo reference="left_arm_3_link">
    <turnGravityOff>false</turnGravityOff>
    <selfCollide>true</selfCollide>
    <material>Gazebo/Orange</material>
  </gazebo>
  <gazebo reference="left_arm_4_link">
    <turnGravityOff>false</turnGravityOff>
    <selfCollide>true</selfCollide>
    <material>Gazebo/Orange</material>
  </gazebo>
  <gazebo reference="left_arm_5_link">
    <turnGravityOff>false</turnGravityOff>
    <selfCollide>true</selfCollide>
    <material>Gazebo/Orange</material>
  </gazebo>
  <gazebo reference="left_arm_6_link">
    <turnGravityOff>false</turnGravityOff>
    <selfCollide>true</selfCollide>
    <material>Gazebo/Grey</material>
  </gazebo>
  <gazebo reference="left_arm_6_joint">
    <provideFeedback>true</provideFeedback>
  </gazebo>
  <gazebo reference="left_arm_7_link">
    <turnGravityOff>false</turnGravityOff>
    <selfCollide>true</selfCollide>
    <material>Gazebo/Grey</material>
  </gazebo>
  <!--
    <transmission name="${name}_arm_0_trans" type="SimpleTransmission">
      <actuator name="${name}_arm_0_motor" />
      <joint name="${name}_arm_0_joint" />
      <mechanicalReduction>1.0</mechanicalReduction>
    </transmission>
    <transmission name="${name}_arm_1_trans" type="SimpleTransmission">
      <actuator name="${name}_arm_1_motor" />
      <joint name="${name}_arm_1_joint" />
      <mechanicalReduction>1.0</mechanicalReduction>
    </transmission>
    <transmission name="${name}_arm_2_trans" type="SimpleTransmission">
      <actuator name="${name}_arm_2_motor" />
      <joint name="${name}_arm_2_joint" />
      <mechanicalReduction>1.0</mechanicalReduction>
    </transmission>
    <transmission name="${name}_arm_3_trans" type="SimpleTransmission">
      <actuator name="${name}_arm_3_motor" />
      <joint name="${name}_arm_3_joint" />
      <mechanicalReduction>1.0</mechanicalReduction>
    </transmission>
    <transmission name="${name}_arm_4_trans" type="SimpleTransmission">
      <actuator name="${name}_arm_4_motor" />
      <joint name="${name}_arm_4_joint" />
      <mechanicalReduction>1.0</mechanicalReduction>
    </transmission>
    <transmission name="${name}_arm_5_trans" type="SimpleTransmission">
      <actuator name="${name}_arm_5_motor" />
      <joint name="${name}_arm_5_joint" />
      <mechanicalReduction>1.0</mechanicalReduction>
    </transmission>
    <transmission name="${name}_arm_6_trans" type="SimpleTransmission">
      <actuator name="${name}_arm_6_motor" />
      <joint name="${name}_arm_6_joint" />
      <mechanicalReduction>1.0</mechanicalReduction>
    </transmission>
  -->
  <joint name="right_gripper_mount_joint" type="fixed">
    <origin rpy="0 0 0" xyz="0 0 0"/>
    <parent link="right_arm_ee_link"/>
    <child link="right_gripper_mount_link"/>
  </joint>
  <link name="right_gripper_mount_link">
    <visual>
      <origin rpy="0.0 0 0" xyz="0 0 0"/>
      <geometry>
        <mesh filename="package://velma_description/meshes/gripper_mount_simplified.stl"/>
      </geometry>
      <material name="Orange"/>
    </visual>
    <visual>
      <origin rpy="0.0 0 0" xyz="0 0 0"/>
      <geometry>
        <mesh filename="package://velma_description/meshes/imu_case_right.stl"/>
      </geometry>
      <material name="Orange"/>
    </visual>
    <collision>
      <origin rpy="0 0 0" xyz="0 0 0"/>
      <geometry>
        <mesh filename="package://velma_description/meshes/collision/gripper_mount_collision2.STL"/>
      </geometry>
    </collision>
    <!-- needle -->
    <collision>
      <origin rpy="0 0 0" xyz="0 0 0.07"/>
      <geometry>
        <box size="0.05 0.05 0.14"/>
      </geometry>
    </collision>
    <self_collision_checking>
      <origin rpy="0 0 0" xyz="0 0 0.07"/>
      <geometry>
        <capsule length="0.09" radius="0.025"/>
      </geometry>
    </self_collision_checking>
    <self_collision_checking>
      <origin rpy="0 1.57079632679 0" xyz="0.02 0.0 0.01"/>
      <geometry>
        <capsule length="0.08" radius="0.055"/>
      </geometry>
    </self_collision_checking>
    <inertial>
      <mass value="0.2892125"/>
      <origin rpy="0 0 0" xyz="0.0543534 0.0000315 -0.0313542"/>
      <inertia ixx="0.0007416" ixy="0" ixz="0.000566225" iyy="0.001365025" iyz="0" izz="0.0009347"/>
    </inertial>
    <visual name="black_box1">
      <origin rpy="0 0 0" xyz="0.01 0.01 0.05"/>
      <geometry>
        <box size="0.02 0.02 0.005"/>
      </geometry>
      <material name="Black">
        <color rgba="0 0 0 1.0"/>
      </material>
    </visual>
    <visual name="black_box2">
      <origin rpy="0 0 0" xyz="-0.01 -0.01 0.05"/>
      <geometry>
        <box size="0.02 0.02 0.005"/>
      </geometry>
      <material name="Black">
        <color rgba="0 0 0 1.0"/>
      </material>
    </visual>
    <visual name="white_box1">
      <origin rpy="0 0 0" xyz="0.01 -0.01 0.05"/>
      <geometry>
        <box size="0.02 0.02 0.005"/>
      </geometry>
      <material name="White">
        <color rgba="1 1 1 1.0"/>
      </material>
    </visual>
    <visual name="white_box2">
      <origin rpy="0 0 0" xyz="-0.01 0.01 0.05"/>
      <geometry>
        <box size="0.02 0.02 0.005"/>
      </geometry>
      <material name="White">
        <color rgba="1 1 1 1.0"/>
      </material>
    </visual>
  </link>
  <joint name="right_needle_joint" type="fixed">
    <origin rpy="0 0 0" xyz="0.0011 -0.0008 0.1126"/>
    <parent link="right_arm_ee_link"/>
    <child link="right_needle_link"/>
  </joint>
  <link name="right_needle_link">
    <inertial>
      <mass value="0"/>
      <origin rpy="0 0 0" xyz="0 0 0"/>
      <inertia ixx="0" ixy="0" ixz="0" iyy="0" iyz="0" izz="0"/>
    </inertial>
  </link>
  <joint name="left_needle_joint" type="fixed">
    <origin rpy="0 0 0" xyz="-0.001 0.0008 0.106"/>
    <parent link="left_arm_ee_link"/>
    <child link="left_needle_link"/>
  </joint>
  <link name="left_needle_link">
    <inertial>
      <mass value="0"/>
      <origin rpy="0 0 0" xyz="0 0 0"/>
      <inertia ixx="0" ixy="0" ixz="0" iyy="0" iyz="0" izz="0"/>
    </inertial>
  </link>
  <!--
gripper mount link:
density: 1
LOG: 2 Mesh Volume  is 0.000115685
LOG: 2 Thin shell barycenter   0.546513   0.000319  -0.310379
LOG: 2 Center of Mass  is 0.0543534 0.0000315 -0.0313542
LOG: 2 Inertia Tensor is :
LOG: 2     |  0.00000029664   0.00000000000   0.00000022649 |
LOG: 2     |  0.00000000000   0.00000054601  -0.00000000000 |
LOG: 2     |  0.00000022649  -0.00000000000   0.00000037388 |
LOG: 2 Principal axes are :
LOG: 2     |  0.764229   0.000001   0.644945 |
LOG: 2     | -0.000000   1.000000  -0.000001 |
LOG: 2     | -0.644945   0.000001   0.764229 |
LOG: 2 axis momenta are :
LOG: 2     |  0.010550   0.054601   0.056502 |
-->
  <gazebo reference="right_gripper_mount_link">
    <turnGravityOff>false</turnGravityOff>
    <selfCollide>true</selfCollide>
  </gazebo>
  <joint name="left_gripper_mount_joint" type="fixed">
    <origin rpy="0 0 3.14159265359" xyz="0 0 0"/>
    <parent link="left_arm_ee_link"/>
    <child link="left_gripper_mount_link"/>
  </joint>
  <link name="left_gripper_mount_link">
    <visual>
      <origin rpy="0.0 0 0" xyz="0 0 0"/>
      <geometry>
        <mesh filename="package://velma_description/meshes/gripper_mount_simplified.stl"/>
      </geometry>
      <material name="Orange"/>
    </visual>
    <collision>
      <origin rpy="0 0 0" xyz="0 0 0"/>
      <geometry>
        <mesh filename="package://velma_description/meshes/collision/gripper_mount_collision2.STL"/>
      </geometry>
    </collision>
    <!-- needle -->
    <collision>
      <origin rpy="0 0 0" xyz="0 0 0.07"/>
      <geometry>
        <box size="0.05 0.05 0.14"/>
      </geometry>
    </collision>
    <self_collision_checking>
      <origin rpy="0 0 0" xyz="0 0 0.07"/>
      <geometry>
        <capsule length="0.09" radius="0.025"/>
      </geometry>
    </self_collision_checking>
    <self_collision_checking>
      <origin rpy="0 1.57079632679 0" xyz="0.02 0.0 -0.01"/>
      <geometry>
        <capsule length="0.08" radius="0.055"/>
      </geometry>
    </self_collision_checking>
    <inertial>
      <mass value="0.2892125"/>
      <origin rpy="0 0 0" xyz="0.0543534 0.0000315 -0.0313542"/>
      <inertia ixx="0.0007416" ixy="0" ixz="0.000566225" iyy="0.001365025" iyz="0" izz="0.0009347"/>
    </inertial>
    <visual name="black_box1">
      <origin rpy="0 0 0" xyz="0.01 0.01 0.02"/>
      <geometry>
        <box size="0.02 0.02 0.005"/>
      </geometry>
      <material name="Black">
        <color rgba="0 0 0 1.0"/>
      </material>
    </visual>
    <visual name="black_box2">
      <origin rpy="0 0 0" xyz="-0.01 -0.01 0.02"/>
      <geometry>
        <box size="0.02 0.02 0.005"/>
      </geometry>
      <material name="Black">
        <color rgba="0 0 0 1.0"/>
      </material>
    </visual>
    <visual name="white_box1">
      <origin rpy="0 0 0" xyz="0.01 -0.01 0.02"/>
      <geometry>
        <box size="0.02 0.02 0.005"/>
      </geometry>
      <material name="White">
        <color rgba="1 1 1 1.0"/>
      </material>
    </visual>
    <visual name="white_box2">
      <origin rpy="0 0 0" xyz="-0.01 0.01 0.02"/>
      <geometry>
        <box size="0.02 0.02 0.005"/>
      </geometry>
      <material name="White">
        <color rgba="1 1 1 1.0"/>
      </material>
    </visual>
  </link>
  <gazebo reference="left_gripper_mount_link">
    <turnGravityOff>false</turnGravityOff>
    <selfCollide>true</selfCollide>
  </gazebo>
  <link name="right_FtSensorLink">
    <inertial>
      <mass value="0.002"/>
      <origin rpy="0 0 0" xyz="0 0 0"/>
      <inertia ixx="0.00000520833333333" ixy="0" ixz="0" iyy="0.00000520833333333" iyz="0" izz="0.00000520833333333"/>
    </inertial>
  </link>
  <gazebo reference="right_FtSensorLink">
    <turnGravityOff>false</turnGravityOff>
    <selfCollide>true</selfCollide>
  </gazebo>
  <joint name="rightFtSensorJoint" type="revolute">
    <parent link="right_gripper_mount_link"/>
    <child link="right_FtSensorLink"/>
    <!-- 39.56 degrees -->
    <origin rpy="0 1.57079632679 0" xyz="0.115 0.0 -0.078"/>
    <axis xyz="0 0 1"/>
    <!-- measured max angle is 94.  so upper limit is 94 - start orientation (42 degrees)-->
    <limit effort="10" lower="0" upper="0.00001" velocity="3.27"/>
    <dynamics damping="0.05"/>
  </joint>
  <gazebo reference="rightFtSensorJoint">
    <provideFeedback>true</provideFeedback>
  </gazebo>
  <link name="right_HandPalmLink">
    <inertial>
      <origin xyz="0.00035500 -0.00499005 0.04864979"/>
      <mass value="0.63352875"/>
      <inertia ixx="0.00102103" ixy="0.00000775" ixz="-0.00001230" iyy="0.00080944" iyz="-0.00014417" izz="0.00068788"/>
    </inertial>
    <visual>
      <origin rpy="0 0 0" xyz="0 0 0"/>
      <geometry>
        <mesh filename="package://barrett_hand_defs/meshes/palm.stl"/>
      </geometry>
      <material name="bh_HandGrey"/>
    </visual>
    <collision>
      <origin rpy="0 0 0" xyz="0 0 0.029"/>
      <geometry>
        <sphere radius="0.049"/>
      </geometry>
    </collision>
    <collision>
      <origin rpy="0 0 0" xyz="0 0 0.0578880161047"/>
      <geometry>
        <box size="0.0905260443687 0.0546207651496 0.0420634746552"/>
      </geometry>
    </collision>
    <collision>
      <origin rpy="0 0 0" xyz="0 -0.0385280400515 0.0572689175606"/>
      <geometry>
        <box size="0.0275810360909 0.0546207651496 0.0339374542236"/>
      </geometry>
    </collision>
    <collision>
      <origin rpy="0 0 0" xyz="0 -0.0487826019526 0.0744814276695"/>
      <geometry>
        <sphere radius="0.0194399058819"/>
      </geometry>
    </collision>
    <!-- collision mesh used for RT self-collision avoidance -->
    <!-- <self_collision_checking>
        <origin xyz="0 0 0" rpy="0 0 0"/>
        <geometry>
          <convex>
            <point xyz="0.03 0.03 0.0" frame="${prefix}_HandPalmLink"/>
            <point xyz="-0.03 0.03 0.0" frame="${prefix}_HandPalmLink"/>
            <point xyz="-0.03 -0.03 0.0" frame="${prefix}_HandPalmLink"/>
            <point xyz="0.03 -0.03 0.0" frame="${prefix}_HandPalmLink"/>

            <point xyz="0.06 0 0" frame="${prefix}_HandFingerOneKnuckleOneLink"/>
            <point xyz="0.06 0 0" frame="${prefix}_HandFingerTwoKnuckleOneLink"/>
            <point xyz="0 -0.06 0.06" frame="${prefix}_HandPalmLink"/>

            <point xyz="0 0 0" frame="${prefix}_HandFingerOneKnuckleThreeLink"/>
            <point xyz="0 0 0" frame="${prefix}_HandFingerTwoKnuckleThreeLink"/>
            <point xyz="0 0 0" frame="${prefix}_HandFingerThreeKnuckleThreeLink"/>

            <point xyz="0.06 0 0" frame="${prefix}_HandFingerOneKnuckleThreeLink"/>
            <point xyz="0.06 0 0" frame="${prefix}_HandFingerTwoKnuckleThreeLink"/>
            <point xyz="0.06 0 0" frame="${prefix}_HandFingerThreeKnuckleThreeLink"/>
          </convex>
        </geometry>
      </self_collision_checking> -->
    <self_collision_checking>
      <origin rpy="0 0 0" xyz="0.0 0.0 0.03"/>
      <geometry>
        <sphere radius="0.06"/>
      </geometry>
    </self_collision_checking>
  </link>
  <gazebo reference="right_HandPalmLink">
    <turnGravityOff>false</turnGravityOff>
    <selfCollide>true</selfCollide>
  </gazebo>
  <joint name="right_HandPalmMarkerAJoint" type="fixed">
    <parent link="right_HandPalmLink"/>
    <child link="right_HandPalmMarkerALink"/>
    <origin rpy="0 1.57079632679 0" xyz="0.0445 0.0 0.0255"/>
  </joint>
  <link name="right_HandPalmMarkerALink">
    <inertial>
      <mass value="0"/>
      <origin rpy="0 0 0" xyz="0 0 0"/>
      <inertia ixx="0" ixy="0" ixz="0" iyy="0" iyz="0" izz="0"/>
    </inertial>
  </link>
  <joint name="right_HandPalmMarkerCJoint" type="fixed">
    <parent link="right_HandPalmLink"/>
    <child link="right_HandPalmMarkerCLink"/>
    <origin rpy="0 -1.57079632679 0" xyz="-0.0445 0.0 0.0255"/>
  </joint>
  <link name="right_HandPalmMarkerCLink">
    <inertial>
      <mass value="0"/>
      <origin rpy="0 0 0" xyz="0 0 0"/>
      <inertia ixx="0" ixy="0" ixz="0" iyy="0" iyz="0" izz="0"/>
    </inertial>
  </link>
  <joint name="right_HandPalmMarkerBJoint" type="fixed">
    <parent link="right_HandPalmLink"/>
    <child link="right_HandPalmMarkerBLink"/>
    <origin rpy="-1.57079632679 0 0" xyz="0.0 0.0445 0.0255"/>
  </joint>
  <link name="right_HandPalmMarkerBLink">
    <inertial>
      <mass value="0"/>
      <origin rpy="0 0 0" xyz="0 0 0"/>
      <inertia ixx="0" ixy="0" ixz="0" iyy="0" iyz="0" izz="0"/>
    </inertial>
  </link>
  <joint name="right_HandPalmMarkerDJoint" type="fixed">
    <parent link="right_HandPalmLink"/>
    <child link="right_HandPalmMarkerDLink"/>
    <origin rpy="1.57079632679 0 0" xyz="0.0 -0.0445 0.0255"/>
  </joint>
  <link name="right_HandPalmMarkerDLink">
    <inertial>
      <mass value="0"/>
      <origin rpy="0 0 0" xyz="0 0 0"/>
      <inertia ixx="0" ixy="0" ixz="0" iyy="0" iyz="0" izz="0"/>
    </inertial>
  </link>
  <joint name="right_HandPalmJoint" type="fixed">
    <parent link="right_FtSensorLink"/>
    <child link="right_HandPalmLink"/>
    <origin rpy="0 0 0" xyz="0 0 0.005"/>
    <provideFeedback value="true"/>
  </joint>
  <link name="right_HandGripLink">
    <inertial>
      <origin xyz="0.0 0.0 0.0"/>
      <mass value="0.005"/>
      <inertia ixx="0.00000041" ixy="0.00000000" ixz="0.00000016" iyy="0.00000359" iyz="0.00000000" izz="0.00000368"/>
    </inertial>
  </link>
  <gazebo reference="right_HandGripLink">
    <turnGravityOff>false</turnGravityOff>
    <selfCollide>true</selfCollide>
  </gazebo>
  <joint name="right_HandGripJoint" type="fixed">
    <parent link="right_HandPalmLink"/>
    <child link="right_HandGripLink"/>
    <origin rpy="0 0 0" xyz="0 0 0.12"/>
  </joint>
  <link name="right_HandFingerThreeKnuckleTwoLink">
    <visual>
      <origin rpy="3.14159265359 1.57079632679 0" xyz="0 0 0"/>
      <geometry>
        <mesh filename="package://barrett_hand_defs/meshes/secondFingerLink.stl"/>
      </geometry>
      <material name="bh_HandGrey"/>
    </visual>
    <inertial>
      <origin xyz="0.031720 0.001070 -0.000586"/>
      <mass value="0.057957"/>
      <inertia ixx="0.00000461" ixy="0.00000003" ixz="0.00000164" iyy="0.00003590" iyz="0.00000004" izz="0.00003682"/>
    </inertial>
    <collision>
      <origin rpy="0 0 0.0424077153578" xyz="0.0455318503082 0 0"/>
      <geometry>
        <box size="0.0572708845139 0.0259905532002 0.0224001407623"/>
      </geometry>
    </collision>
    <self_collision_checking>
      <origin rpy="0 1.57075 0" xyz="0.03 0.0 0.0"/>
      <geometry>
        <capsule length="0.06" radius="0.015"/>
      </geometry>
    </self_collision_checking>
    <!--
      <self_collision_checking>
        <origin xyz="0.04 -0.01 0.0" rpy="0 1.57075 -0.5"/>
        <geometry>
          <capsule radius="0.01" length="0.1"/>
        </geometry>
      </self_collision_checking>
-->
  </link>
  <gazebo reference="right_HandFingerThreeKnuckleTwoLink">
    <turnGravityOff>false</turnGravityOff>
    <selfCollide>true</selfCollide>
  </gazebo>
  <joint name="right_HandFingerThreeKnuckleTwoJoint" type="revolute">
    <parent link="right_HandPalmLink"/>
    <child link="right_HandFingerThreeKnuckleTwoLink"/>
    <origin rpy="-1.57079632679 0 -1.57079632679" xyz="0 -0.05 0.0754"/>
    <axis xyz="0 0 -1"/>
    <!-- 122 degrees - start orientation of 0.4 degrees-->
    <limit effort="2" lower="0" upper="2.443388889" velocity="3.27"/>
    <dynamics damping="0.05"/>
  </joint>
  <gazebo reference="right_HandFingerThreeKnuckleTwoJoint">
    <provideFeedback>true</provideFeedback>
  </gazebo>
  <link name="right_HandFingerThreeKnuckleThreeLink">
    <visual>
      <origin rpy="0 0 0" xyz="0 0 0"/>
      <geometry>
        <mesh filename="package://barrett_hand_defs/meshes/thirdFingerLink.stl"/>
      </geometry>
      <material name="bh_HandGrey"/>
    </visual>
    <!--      <inertial>
        <origin xyz="0.01970974 0.00182016 0.00020041" />
        <mass value="0.03421781" />
        <inertia  ixx="0.00000287" ixy="0.00000091"  ixz="-0.00000007"
                                   iyy="0.00001329"  iyz="-0.00000002"
                                                     izz="0.00001214" />
      </inertial>
-->
    <inertial>
      <origin xyz="0.01970974 0.00182016 0.00020041"/>
      <mass value="0.03421781"/>
      <inertia ixx="0.00000461" ixy="0.00000003" ixz="0.00000164" iyy="0.00003590" iyz="0.00000004" izz="0.00003682"/>
    </inertial>
    <collision>
      <origin rpy="0 0 0" xyz="0.0220463573933 0 0"/>
      <geometry>
        <box size="0.0456312298775 0.0218328088522 0.0227420330048"/>
      </geometry>
    </collision>
    <collision>
      <origin rpy="0 0 0" xyz="0.046044960618 0.001 0"/>
      <geometry>
        <sphere radius="0.012090086937"/>
      </geometry>
    </collision>
    <self_collision_checking>
      <origin rpy="0 1.57075 0" xyz="0.025 0.0 0.0"/>
      <geometry>
        <capsule length="0.05" radius="0.015"/>
      </geometry>
    </self_collision_checking>
  </link>
  <gazebo reference="right_HandFingerThreeKnuckleThreeLink">
    <turnGravityOff>false</turnGravityOff>
    <selfCollide>true</selfCollide>
  </gazebo>
  <joint name="right_HandFingerThreeKnuckleThreeJoint" type="revolute">
    <parent link="right_HandFingerThreeKnuckleTwoLink"/>
    <child link="right_HandFingerThreeKnuckleThreeLink"/>
    <!-- 39.56 degrees -->
    <origin rpy="0 0 -0.690452252" xyz="0.07 0 0"/>
    <axis xyz="0 0 -1"/>
    <!-- measured max angle is 94.  so upper limit is 94 - start orientation (42 degrees)-->
    <limit effort="2" lower="0" upper="0.837733333" velocity="3.27"/>
    <dynamics damping="0.05"/>
  </joint>
  <gazebo reference="right_HandFingerThreeKnuckleThreeJoint">
    <provideFeedback>true</provideFeedback>
  </gazebo>
  <link name="right_HandFingerOneKnuckleOneLink">
    <visual>
      <origin rpy="1.57079632679 0 -1.57079632679" xyz="0 0 -0.0045"/>
      <geometry>
        <mesh filename="package://barrett_hand_defs/meshes/firstFingerLink.stl"/>
      </geometry>
      <material name="bh_HandGrey"/>
    </visual>
    <inertial>
      <origin xyz="0.03201666 -0.00086502 0.00890075"/>
      <mass value="0.16252678"/>
      <inertia ixx="0.00002567" ixy="-0.00000146" ixz="0.00001128" iyy="0.00008818" iyz="-0.00000094" izz="0.00007827"/>
    </inertial>
    <collision>
      <origin rpy="0 0 0" xyz="0.0270798802376 0 0.00195854902267"/>
      <geometry>
        <box size="0.0752255320549 0.0278776362538 0.0362581014633"/>
      </geometry>
    </collision>
    <collision>
      <origin rpy="0 0 0" xyz="0.0493242815137 0 0.0150546580553"/>
      <geometry>
        <sphere radius="0.0196040868759"/>
      </geometry>
    </collision>
  </link>
  <gazebo reference="right_HandFingerOneKnuckleOneLink">
    <turnGravityOff>false</turnGravityOff>
    <selfCollide>true</selfCollide>
  </gazebo>
  <joint name="right_HandFingerOneKnuckleOneJoint" type="revolute">
    <parent link="right_HandPalmLink"/>
    <child link="right_HandFingerOneKnuckleOneLink"/>
    <origin rpy="0 0 1.57079632679" xyz="0.02497 0 0.0587966"/>
    <axis xyz="0 0 -1"/>
    <limit effort="2" lower="0" upper="3.14159265359" velocity="3.27"/>
    <dynamics damping="0.1"/>
  </joint>
  <gazebo reference="right_HandFingerOneKnuckleOneJoint">
    <provideFeedback>true</provideFeedback>
  </gazebo>
  <link name="right_HandFingerOneKnuckleTwoLink">
    <visual>
      <origin rpy="3.14159265359 1.57079632679 0" xyz="0 0 0"/>
      <geometry>
        <mesh filename="package://barrett_hand_defs/meshes/secondFingerLink.stl"/>
      </geometry>
      <material name="bh_HandGrey"/>
    </visual>
    <inertial>
      <origin xyz="0.031720 0.001070 -0.000586"/>
      <mass value="0.057957"/>
      <inertia ixx="0.00000461" ixy="0.00000003" ixz="0.00000164" iyy="0.00003590" iyz="0.00000004" izz="0.00003682"/>
    </inertial>
    <collision>
      <origin rpy="0 0 0.0424077153578" xyz="0.0455318503082 0 0"/>
      <geometry>
        <box size="0.0572708845139 0.0259905532002 0.0224001407623"/>
      </geometry>
    </collision>
    <self_collision_checking>
      <origin rpy="0 1.57075 0" xyz="0.03 0.0 0.0"/>
      <geometry>
        <capsule length="0.06" radius="0.015"/>
      </geometry>
    </self_collision_checking>
    <!--
      <self_collision_checking>
        <origin xyz="0.04 -0.01 0.0" rpy="0 1.57075 -0.5"/>
        <geometry>
          <capsule radius="0.01" length="0.1"/>
        </geometry>
      </self_collision_checking>
-->
  </link>
  <gazebo reference="right_HandFingerOneKnuckleTwoLink">
    <turnGravityOff>false</turnGravityOff>
    <selfCollide>true</selfCollide>
  </gazebo>
  <joint name="right_HandFingerOneKnuckleTwoJoint" type="revolute">
    <parent link="right_HandFingerOneKnuckleOneLink"/>
    <child link="right_HandFingerOneKnuckleTwoLink"/>
    <origin rpy="-1.57079632679 0 0" xyz="0.05 0 0.0166034"/>
    <axis xyz="0 0 -1"/>
    <!-- 122 degrees - start orientation of 0.4 degrees-->
    <limit effort="2" lower="0" upper="2.443388889" velocity="3.27"/>
    <dynamics damping="0.05"/>
  </joint>
  <gazebo reference="right_HandFingerOneKnuckleTwoJoint">
    <provideFeedback>true</provideFeedback>
  </gazebo>
  <link name="right_HandFingerOneKnuckleThreeLink">
    <visual>
      <origin rpy="0 0 0" xyz="0 0 0"/>
      <geometry>
        <mesh filename="package://barrett_hand_defs/meshes/thirdFingerLink.stl"/>
      </geometry>
      <material name="bh_HandGrey"/>
    </visual>
    <!--      <inertial>
        <origin xyz="0.01970974 0.00182016 0.00020041" />
        <mass value="0.03421781" />
        <inertia  ixx="0.00000287" ixy="0.00000091"  ixz="-0.00000007"
                                   iyy="0.00001329"  iyz="-0.00000002"
                                                     izz="0.00001214" />
      </inertial>
-->
    <inertial>
      <origin xyz="0.01970974 0.00182016 0.00020041"/>
      <mass value="0.03421781"/>
      <inertia ixx="0.00000461" ixy="0.00000003" ixz="0.00000164" iyy="0.00003590" iyz="0.00000004" izz="0.00003682"/>
    </inertial>
    <collision>
      <origin rpy="0 0 0" xyz="0.0220463573933 0 0"/>
      <geometry>
        <box size="0.0456312298775 0.0218328088522 0.0227420330048"/>
      </geometry>
    </collision>
    <collision>
      <origin rpy="0 0 0" xyz="0.046044960618 0.001 0"/>
      <geometry>
        <sphere radius="0.012090086937"/>
      </geometry>
    </collision>
    <self_collision_checking>
      <origin rpy="0 1.57075 0" xyz="0.025 0.0 0.0"/>
      <geometry>
        <capsule length="0.05" radius="0.015"/>
      </geometry>
    </self_collision_checking>
  </link>
  <gazebo reference="right_HandFingerOneKnuckleThreeLink">
    <turnGravityOff>false</turnGravityOff>
    <selfCollide>true</selfCollide>
  </gazebo>
  <joint name="right_HandFingerOneKnuckleThreeJoint" type="revolute">
    <parent link="right_HandFingerOneKnuckleTwoLink"/>
    <child link="right_HandFingerOneKnuckleThreeLink"/>
    <!-- 39.56 degrees -->
    <origin rpy="0 0 -0.690452252" xyz="0.07 0 0"/>
    <axis xyz="0 0 -1"/>
    <!-- measured max angle is 94.  so upper limit is 94 - start orientation (42 degrees)-->
    <limit effort="2" lower="0" upper="0.837733333" velocity="3.27"/>
    <dynamics damping="0.05"/>
  </joint>
  <gazebo reference="right_HandFingerOneKnuckleThreeJoint">
    <provideFeedback>true</provideFeedback>
  </gazebo>
  <link name="right_HandFingerTwoKnuckleOneLink">
    <visual>
      <origin rpy="1.57079632679 0 -1.57079632679" xyz="0 0 -0.0045"/>
      <geometry>
        <mesh filename="package://barrett_hand_defs/meshes/firstFingerLink.stl"/>
      </geometry>
      <material name="bh_HandGrey"/>
    </visual>
    <inertial>
      <origin xyz="0.03201666 -0.00086502 0.00890075"/>
      <mass value="0.16252678"/>
      <inertia ixx="0.00002567" ixy="-0.00000146" ixz="0.00001128" iyy="0.00008818" iyz="-0.00000094" izz="0.00007827"/>
    </inertial>
    <collision>
      <origin rpy="0 0 0" xyz="0.0270798802376 0 0.00195854902267"/>
      <geometry>
        <box size="0.0752255320549 0.0278776362538 0.0362581014633"/>
      </geometry>
    </collision>
    <collision>
      <origin rpy="0 0 0" xyz="0.0493242815137 0 0.0150546580553"/>
      <geometry>
        <sphere radius="0.0196040868759"/>
      </geometry>
    </collision>
  </link>
  <gazebo reference="right_HandFingerTwoKnuckleOneLink">
    <turnGravityOff>false</turnGravityOff>
    <selfCollide>true</selfCollide>
  </gazebo>
  <joint name="right_HandFingerTwoKnuckleOneJoint" type="revolute">
    <parent link="right_HandPalmLink"/>
    <child link="right_HandFingerTwoKnuckleOneLink"/>
    <origin rpy="0 0 1.57079632679" xyz="-0.02497 0 0.0587966"/>
    <axis xyz="0 0 1"/>
    <limit effort="2" lower="0" upper="3.14159265359" velocity="3.27"/>
    <dynamics damping="0.1"/>
  </joint>
  <gazebo reference="right_HandFingerTwoKnuckleOneJoint">
    <provideFeedback>true</provideFeedback>
  </gazebo>
  <link name="right_HandFingerTwoKnuckleTwoLink">
    <visual>
      <origin rpy="3.14159265359 1.57079632679 0" xyz="0 0 0"/>
      <geometry>
        <mesh filename="package://barrett_hand_defs/meshes/secondFingerLink.stl"/>
      </geometry>
      <material name="bh_HandGrey"/>
    </visual>
    <inertial>
      <origin xyz="0.031720 0.001070 -0.000586"/>
      <mass value="0.057957"/>
      <inertia ixx="0.00000461" ixy="0.00000003" ixz="0.00000164" iyy="0.00003590" iyz="0.00000004" izz="0.00003682"/>
    </inertial>
    <collision>
      <origin rpy="0 0 0.0424077153578" xyz="0.0455318503082 0 0"/>
      <geometry>
        <box size="0.0572708845139 0.0259905532002 0.0224001407623"/>
      </geometry>
    </collision>
    <self_collision_checking>
      <origin rpy="0 1.57075 0" xyz="0.03 0.0 0.0"/>
      <geometry>
        <capsule length="0.06" radius="0.015"/>
      </geometry>
    </self_collision_checking>
    <!--
      <self_collision_checking>
        <origin xyz="0.04 -0.01 0.0" rpy="0 1.57075 -0.5"/>
        <geometry>
          <capsule radius="0.01" length="0.1"/>
        </geometry>
      </self_collision_checking>
-->
  </link>
  <gazebo reference="right_HandFingerTwoKnuckleTwoLink">
    <turnGravityOff>false</turnGravityOff>
    <selfCollide>true</selfCollide>
  </gazebo>
  <joint name="right_HandFingerTwoKnuckleTwoJoint" type="revolute">
    <parent link="right_HandFingerTwoKnuckleOneLink"/>
    <child link="right_HandFingerTwoKnuckleTwoLink"/>
    <origin rpy="-1.57079632679 0 0" xyz="0.05 0 0.0166034"/>
    <axis xyz="0 0 -1"/>
    <!-- 122 degrees - start orientation of 0.4 degrees-->
    <limit effort="2" lower="0" upper="2.443388889" velocity="3.27"/>
    <dynamics damping="0.05"/>
  </joint>
  <gazebo reference="right_HandFingerTwoKnuckleTwoJoint">
    <provideFeedback>true</provideFeedback>
  </gazebo>
  <link name="right_HandFingerTwoKnuckleThreeLink">
    <visual>
      <origin rpy="0 0 0" xyz="0 0 0"/>
      <geometry>
        <mesh filename="package://barrett_hand_defs/meshes/thirdFingerLink.stl"/>
      </geometry>
      <material name="bh_HandGrey"/>
    </visual>
    <!--      <inertial>
        <origin xyz="0.01970974 0.00182016 0.00020041" />
        <mass value="0.03421781" />
        <inertia  ixx="0.00000287" ixy="0.00000091"  ixz="-0.00000007"
                                   iyy="0.00001329"  iyz="-0.00000002"
                                                     izz="0.00001214" />
      </inertial>
-->
    <inertial>
      <origin xyz="0.01970974 0.00182016 0.00020041"/>
      <mass value="0.03421781"/>
      <inertia ixx="0.00000461" ixy="0.00000003" ixz="0.00000164" iyy="0.00003590" iyz="0.00000004" izz="0.00003682"/>
    </inertial>
    <collision>
      <origin rpy="0 0 0" xyz="0.0220463573933 0 0"/>
      <geometry>
        <box size="0.0456312298775 0.0218328088522 0.0227420330048"/>
      </geometry>
    </collision>
    <collision>
      <origin rpy="0 0 0" xyz="0.046044960618 0.001 0"/>
      <geometry>
        <sphere radius="0.012090086937"/>
      </geometry>
    </collision>
    <self_collision_checking>
      <origin rpy="0 1.57075 0" xyz="0.025 0.0 0.0"/>
      <geometry>
        <capsule length="0.05" radius="0.015"/>
      </geometry>
    </self_collision_checking>
  </link>
  <gazebo reference="right_HandFingerTwoKnuckleThreeLink">
    <turnGravityOff>false</turnGravityOff>
    <selfCollide>true</selfCollide>
  </gazebo>
  <joint name="right_HandFingerTwoKnuckleThreeJoint" type="revolute">
    <parent link="right_HandFingerTwoKnuckleTwoLink"/>
    <child link="right_HandFingerTwoKnuckleThreeLink"/>
    <!-- 39.56 degrees -->
    <origin rpy="0 0 -0.690452252" xyz="0.07 0 0"/>
    <axis xyz="0 0 -1"/>
    <!-- measured max angle is 94.  so upper limit is 94 - start orientation (42 degrees)-->
    <limit effort="2" lower="0" upper="0.837733333" velocity="3.27"/>
    <dynamics damping="0.05"/>
  </joint>
  <gazebo reference="right_HandFingerTwoKnuckleThreeJoint">
    <provideFeedback>true</provideFeedback>
  </gazebo>
  <!-- <xacro:fingers prefix="${prefix}" parent="${prefix}_HandFingerTwoKnuckleOneLink" number="Two" xyz="0.05 0 0.0166034" rpy="-${0.5 * PI} -0.0429350996 0"/> -->
  <link name="left_FtSensorLink">
    <inertial>
      <mass value="0.002"/>
      <origin rpy="0 0 0" xyz="0 0 0"/>
      <inertia ixx="0.00000520833333333" ixy="0" ixz="0" iyy="0.00000520833333333" iyz="0" izz="0.00000520833333333"/>
    </inertial>
  </link>
  <gazebo reference="left_FtSensorLink">
    <turnGravityOff>false</turnGravityOff>
    <selfCollide>true</selfCollide>
  </gazebo>
  <joint name="leftFtSensorJoint" type="revolute">
    <parent link="left_gripper_mount_link"/>
    <child link="left_FtSensorLink"/>
    <!-- 39.56 degrees -->
    <origin rpy="0 1.57079632679 0" xyz="0.115 0.0 -0.078"/>
    <axis xyz="0 0 1"/>
    <!-- measured max angle is 94.  so upper limit is 94 - start orientation (42 degrees)-->
    <limit effort="10" lower="0" upper="0.00001" velocity="3.27"/>
    <dynamics damping="0.05"/>
  </joint>
  <gazebo reference="leftFtSensorJoint">
    <provideFeedback>true</provideFeedback>
  </gazebo>
  <link name="left_HandPalmLink">
    <inertial>
      <origin xyz="0.00035500 -0.00499005 0.04864979"/>
      <mass value="0.63352875"/>
      <inertia ixx="0.00102103" ixy="0.00000775" ixz="-0.00001230" iyy="0.00080944" iyz="-0.00014417" izz="0.00068788"/>
    </inertial>
    <visual>
      <origin rpy="0 0 0" xyz="0 0 0"/>
      <geometry>
        <mesh filename="package://barrett_hand_defs/meshes/palm.stl"/>
      </geometry>
      <material name="bh_HandGrey"/>
    </visual>
    <collision>
      <origin rpy="0 0 0" xyz="0 0 0.029"/>
      <geometry>
        <sphere radius="0.049"/>
      </geometry>
    </collision>
    <collision>
      <origin rpy="0 0 0" xyz="0 0 0.0578880161047"/>
      <geometry>
        <box size="0.0905260443687 0.0546207651496 0.0420634746552"/>
      </geometry>
    </collision>
    <collision>
      <origin rpy="0 0 0" xyz="0 -0.0385280400515 0.0572689175606"/>
      <geometry>
        <box size="0.0275810360909 0.0546207651496 0.0339374542236"/>
      </geometry>
    </collision>
    <collision>
      <origin rpy="0 0 0" xyz="0 -0.0487826019526 0.0744814276695"/>
      <geometry>
        <sphere radius="0.0194399058819"/>
      </geometry>
    </collision>
    <!-- collision mesh used for RT self-collision avoidance -->
    <!-- <self_collision_checking>
        <origin xyz="0 0 0" rpy="0 0 0"/>
        <geometry>
          <convex>
            <point xyz="0.03 0.03 0.0" frame="${prefix}_HandPalmLink"/>
            <point xyz="-0.03 0.03 0.0" frame="${prefix}_HandPalmLink"/>
            <point xyz="-0.03 -0.03 0.0" frame="${prefix}_HandPalmLink"/>
            <point xyz="0.03 -0.03 0.0" frame="${prefix}_HandPalmLink"/>

            <point xyz="0.06 0 0" frame="${prefix}_HandFingerOneKnuckleOneLink"/>
            <point xyz="0.06 0 0" frame="${prefix}_HandFingerTwoKnuckleOneLink"/>
            <point xyz="0 -0.06 0.06" frame="${prefix}_HandPalmLink"/>

            <point xyz="0 0 0" frame="${prefix}_HandFingerOneKnuckleThreeLink"/>
            <point xyz="0 0 0" frame="${prefix}_HandFingerTwoKnuckleThreeLink"/>
            <point xyz="0 0 0" frame="${prefix}_HandFingerThreeKnuckleThreeLink"/>

            <point xyz="0.06 0 0" frame="${prefix}_HandFingerOneKnuckleThreeLink"/>
            <point xyz="0.06 0 0" frame="${prefix}_HandFingerTwoKnuckleThreeLink"/>
            <point xyz="0.06 0 0" frame="${prefix}_HandFingerThreeKnuckleThreeLink"/>
          </convex>
        </geometry>
      </self_collision_checking> -->
    <self_collision_checking>
      <origin rpy="0 0 0" xyz="0.0 0.0 0.03"/>
      <geometry>
        <sphere radius="0.06"/>
      </geometry>
    </self_collision_checking>
  </link>
  <gazebo reference="left_HandPalmLink">
    <turnGravityOff>false</turnGravityOff>
    <selfCollide>true</selfCollide>
  </gazebo>
  <joint name="left_HandPalmMarkerAJoint" type="fixed">
    <parent link="left_HandPalmLink"/>
    <child link="left_HandPalmMarkerALink"/>
    <origin rpy="0 1.57079632679 0" xyz="0.0445 0.0 0.0255"/>
  </joint>
  <link name="left_HandPalmMarkerALink">
    <inertial>
      <mass value="0"/>
      <origin rpy="0 0 0" xyz="0 0 0"/>
      <inertia ixx="0" ixy="0" ixz="0" iyy="0" iyz="0" izz="0"/>
    </inertial>
  </link>
  <joint name="left_HandPalmMarkerCJoint" type="fixed">
    <parent link="left_HandPalmLink"/>
    <child link="left_HandPalmMarkerCLink"/>
    <origin rpy="0 -1.57079632679 0" xyz="-0.0445 0.0 0.0255"/>
  </joint>
  <link name="left_HandPalmMarkerCLink">
    <inertial>
      <mass value="0"/>
      <origin rpy="0 0 0" xyz="0 0 0"/>
      <inertia ixx="0" ixy="0" ixz="0" iyy="0" iyz="0" izz="0"/>
    </inertial>
  </link>
  <joint name="left_HandPalmMarkerBJoint" type="fixed">
    <parent link="left_HandPalmLink"/>
    <child link="left_HandPalmMarkerBLink"/>
    <origin rpy="-1.57079632679 0 0" xyz="0.0 0.0445 0.0255"/>
  </joint>
  <link name="left_HandPalmMarkerBLink">
    <inertial>
      <mass value="0"/>
      <origin rpy="0 0 0" xyz="0 0 0"/>
      <inertia ixx="0" ixy="0" ixz="0" iyy="0" iyz="0" izz="0"/>
    </inertial>
  </link>
  <joint name="left_HandPalmMarkerDJoint" type="fixed">
    <parent link="left_HandPalmLink"/>
    <child link="left_HandPalmMarkerDLink"/>
    <origin rpy="1.57079632679 0 0" xyz="0.0 -0.0445 0.0255"/>
  </joint>
  <link name="left_HandPalmMarkerDLink">
    <inertial>
      <mass value="0"/>
      <origin rpy="0 0 0" xyz="0 0 0"/>
      <inertia ixx="0" ixy="0" ixz="0" iyy="0" iyz="0" izz="0"/>
    </inertial>
  </link>
  <joint name="left_HandPalmJoint" type="fixed">
    <parent link="left_FtSensorLink"/>
    <child link="left_HandPalmLink"/>
    <origin rpy="0 0 3.14159265359" xyz="0 0 0.005"/>
    <provideFeedback value="true"/>
  </joint>
  <link name="left_HandGripLink">
    <inertial>
      <origin xyz="0.0 0.0 0.0"/>
      <mass value="0.005"/>
      <inertia ixx="0.00000041" ixy="0.00000000" ixz="0.00000016" iyy="0.00000359" iyz="0.00000000" izz="0.00000368"/>
    </inertial>
  </link>
  <gazebo reference="left_HandGripLink">
    <turnGravityOff>false</turnGravityOff>
    <selfCollide>true</selfCollide>
  </gazebo>
  <joint name="left_HandGripJoint" type="fixed">
    <parent link="left_HandPalmLink"/>
    <child link="left_HandGripLink"/>
    <origin rpy="0 0 0" xyz="0 0 0.12"/>
  </joint>
  <link name="left_HandFingerThreeKnuckleTwoLink">
    <visual>
      <origin rpy="3.14159265359 1.57079632679 0" xyz="0 0 0"/>
      <geometry>
        <mesh filename="package://barrett_hand_defs/meshes/secondFingerLink.stl"/>
      </geometry>
      <material name="bh_HandGrey"/>
    </visual>
    <inertial>
      <origin xyz="0.031720 0.001070 -0.000586"/>
      <mass value="0.057957"/>
      <inertia ixx="0.00000461" ixy="0.00000003" ixz="0.00000164" iyy="0.00003590" iyz="0.00000004" izz="0.00003682"/>
    </inertial>
    <collision>
      <origin rpy="0 0 0.0424077153578" xyz="0.0455318503082 0 0"/>
      <geometry>
        <box size="0.0572708845139 0.0259905532002 0.0224001407623"/>
      </geometry>
    </collision>
    <self_collision_checking>
      <origin rpy="0 1.57075 0" xyz="0.03 0.0 0.0"/>
      <geometry>
        <capsule length="0.06" radius="0.015"/>
      </geometry>
    </self_collision_checking>
    <!--
      <self_collision_checking>
        <origin xyz="0.04 -0.01 0.0" rpy="0 1.57075 -0.5"/>
        <geometry>
          <capsule radius="0.01" length="0.1"/>
        </geometry>
      </self_collision_checking>
-->
  </link>
  <gazebo reference="left_HandFingerThreeKnuckleTwoLink">
    <turnGravityOff>false</turnGravityOff>
    <selfCollide>true</selfCollide>
  </gazebo>
  <joint name="left_HandFingerThreeKnuckleTwoJoint" type="revolute">
    <parent link="left_HandPalmLink"/>
    <child link="left_HandFingerThreeKnuckleTwoLink"/>
    <origin rpy="-1.57079632679 0 -1.57079632679" xyz="0 -0.05 0.0754"/>
    <axis xyz="0 0 -1"/>
    <!-- 122 degrees - start orientation of 0.4 degrees-->
    <limit effort="2" lower="0" upper="2.443388889" velocity="3.27"/>
    <dynamics damping="0.05"/>
  </joint>
  <gazebo reference="left_HandFingerThreeKnuckleTwoJoint">
    <provideFeedback>true</provideFeedback>
  </gazebo>
  <link name="left_HandFingerThreeKnuckleThreeLink">
    <visual>
      <origin rpy="0 0 0" xyz="0 0 0"/>
      <geometry>
        <mesh filename="package://barrett_hand_defs/meshes/thirdFingerLink.stl"/>
      </geometry>
      <material name="bh_HandGrey"/>
    </visual>
    <!--      <inertial>
        <origin xyz="0.01970974 0.00182016 0.00020041" />
        <mass value="0.03421781" />
        <inertia  ixx="0.00000287" ixy="0.00000091"  ixz="-0.00000007"
                                   iyy="0.00001329"  iyz="-0.00000002"
                                                     izz="0.00001214" />
      </inertial>
-->
    <inertial>
      <origin xyz="0.01970974 0.00182016 0.00020041"/>
      <mass value="0.03421781"/>
      <inertia ixx="0.00000461" ixy="0.00000003" ixz="0.00000164" iyy="0.00003590" iyz="0.00000004" izz="0.00003682"/>
    </inertial>
    <collision>
      <origin rpy="0 0 0" xyz="0.0220463573933 0 0"/>
      <geometry>
        <box size="0.0456312298775 0.0218328088522 0.0227420330048"/>
      </geometry>
    </collision>
    <collision>
      <origin rpy="0 0 0" xyz="0.046044960618 0.001 0"/>
      <geometry>
        <sphere radius="0.012090086937"/>
      </geometry>
    </collision>
    <self_collision_checking>
      <origin rpy="0 1.57075 0" xyz="0.025 0.0 0.0"/>
      <geometry>
        <capsule length="0.05" radius="0.015"/>
      </geometry>
    </self_collision_checking>
  </link>
  <gazebo reference="left_HandFingerThreeKnuckleThreeLink">
    <turnGravityOff>false</turnGravityOff>
    <selfCollide>true</selfCollide>
  </gazebo>
  <joint name="left_HandFingerThreeKnuckleThreeJoint" type="revolute">
    <parent link="left_HandFingerThreeKnuckleTwoLink"/>
    <child link="left_HandFingerThreeKnuckleThreeLink"/>
    <!-- 39.56 degrees -->
    <origin rpy="0 0 -0.690452252" xyz="0.07 0 0"/>
    <axis xyz="0 0 -1"/>
    <!-- measured max angle is 94.  so upper limit is 94 - start orientation (42 degrees)-->
    <limit effort="2" lower="0" upper="0.837733333" velocity="3.27"/>
    <dynamics damping="0.05"/>
  </joint>
  <gazebo reference="left_HandFingerThreeKnuckleThreeJoint">
    <provideFeedback>true</provideFeedback>
  </gazebo>
  <link name="left_HandFingerOneKnuckleOneLink">
    <visual>
      <origin rpy="1.57079632679 0 -1.57079632679" xyz="0 0 -0.0045"/>
      <geometry>
        <mesh filename="package://barrett_hand_defs/meshes/firstFingerLink.stl"/>
      </geometry>
      <material name="bh_HandGrey"/>
    </visual>
    <inertial>
      <origin xyz="0.03201666 -0.00086502 0.00890075"/>
      <mass value="0.16252678"/>
      <inertia ixx="0.00002567" ixy="-0.00000146" ixz="0.00001128" iyy="0.00008818" iyz="-0.00000094" izz="0.00007827"/>
    </inertial>
    <collision>
      <origin rpy="0 0 0" xyz="0.0270798802376 0 0.00195854902267"/>
      <geometry>
        <box size="0.0752255320549 0.0278776362538 0.0362581014633"/>
      </geometry>
    </collision>
    <collision>
      <origin rpy="0 0 0" xyz="0.0493242815137 0 0.0150546580553"/>
      <geometry>
        <sphere radius="0.0196040868759"/>
      </geometry>
    </collision>
  </link>
  <gazebo reference="left_HandFingerOneKnuckleOneLink">
    <turnGravityOff>false</turnGravityOff>
    <selfCollide>true</selfCollide>
  </gazebo>
  <joint name="left_HandFingerOneKnuckleOneJoint" type="revolute">
    <parent link="left_HandPalmLink"/>
    <child link="left_HandFingerOneKnuckleOneLink"/>
    <origin rpy="0 0 1.57079632679" xyz="0.02497 0 0.0587966"/>
    <axis xyz="0 0 -1"/>
    <limit effort="2" lower="0" upper="3.14159265359" velocity="3.27"/>
    <dynamics damping="0.1"/>
  </joint>
  <gazebo reference="left_HandFingerOneKnuckleOneJoint">
    <provideFeedback>true</provideFeedback>
  </gazebo>
  <link name="left_HandFingerOneKnuckleTwoLink">
    <visual>
      <origin rpy="3.14159265359 1.57079632679 0" xyz="0 0 0"/>
      <geometry>
        <mesh filename="package://barrett_hand_defs/meshes/secondFingerLink.stl"/>
      </geometry>
      <material name="bh_HandGrey"/>
    </visual>
    <inertial>
      <origin xyz="0.031720 0.001070 -0.000586"/>
      <mass value="0.057957"/>
      <inertia ixx="0.00000461" ixy="0.00000003" ixz="0.00000164" iyy="0.00003590" iyz="0.00000004" izz="0.00003682"/>
    </inertial>
    <collision>
      <origin rpy="0 0 0.0424077153578" xyz="0.0455318503082 0 0"/>
      <geometry>
        <box size="0.0572708845139 0.0259905532002 0.0224001407623"/>
      </geometry>
    </collision>
    <self_collision_checking>
      <origin rpy="0 1.57075 0" xyz="0.03 0.0 0.0"/>
      <geometry>
        <capsule length="0.06" radius="0.015"/>
      </geometry>
    </self_collision_checking>
    <!--
      <self_collision_checking>
        <origin xyz="0.04 -0.01 0.0" rpy="0 1.57075 -0.5"/>
        <geometry>
          <capsule radius="0.01" length="0.1"/>
        </geometry>
      </self_collision_checking>
-->
  </link>
  <gazebo reference="left_HandFingerOneKnuckleTwoLink">
    <turnGravityOff>false</turnGravityOff>
    <selfCollide>true</selfCollide>
  </gazebo>
  <joint name="left_HandFingerOneKnuckleTwoJoint" type="revolute">
    <parent link="left_HandFingerOneKnuckleOneLink"/>
    <child link="left_HandFingerOneKnuckleTwoLink"/>
    <origin rpy="-1.57079632679 0 0" xyz="0.05 0 0.0166034"/>
    <axis xyz="0 0 -1"/>
    <!-- 122 degrees - start orientation of 0.4 degrees-->
    <limit effort="2" lower="0" upper="2.443388889" velocity="3.27"/>
    <dynamics damping="0.05"/>
  </joint>
  <gazebo reference="left_HandFingerOneKnuckleTwoJoint">
    <provideFeedback>true</provideFeedback>
  </gazebo>
  <link name="left_HandFingerOneKnuckleThreeLink">
    <visual>
      <origin rpy="0 0 0" xyz="0 0 0"/>
      <geometry>
        <mesh filename="package://barrett_hand_defs/meshes/thirdFingerLink.stl"/>
      </geometry>
      <material name="bh_HandGrey"/>
    </visual>
    <!--      <inertial>
        <origin xyz="0.01970974 0.00182016 0.00020041" />
        <mass value="0.03421781" />
        <inertia  ixx="0.00000287" ixy="0.00000091"  ixz="-0.00000007"
                                   iyy="0.00001329"  iyz="-0.00000002"
                                                     izz="0.00001214" />
      </inertial>
-->
    <inertial>
      <origin xyz="0.01970974 0.00182016 0.00020041"/>
      <mass value="0.03421781"/>
      <inertia ixx="0.00000461" ixy="0.00000003" ixz="0.00000164" iyy="0.00003590" iyz="0.00000004" izz="0.00003682"/>
    </inertial>
    <collision>
      <origin rpy="0 0 0" xyz="0.0220463573933 0 0"/>
      <geometry>
        <box size="0.0456312298775 0.0218328088522 0.0227420330048"/>
      </geometry>
    </collision>
    <collision>
      <origin rpy="0 0 0" xyz="0.046044960618 0.001 0"/>
      <geometry>
        <sphere radius="0.012090086937"/>
      </geometry>
    </collision>
    <self_collision_checking>
      <origin rpy="0 1.57075 0" xyz="0.025 0.0 0.0"/>
      <geometry>
        <capsule length="0.05" radius="0.015"/>
      </geometry>
    </self_collision_checking>
  </link>
  <gazebo reference="left_HandFingerOneKnuckleThreeLink">
    <turnGravityOff>false</turnGravityOff>
    <selfCollide>true</selfCollide>
  </gazebo>
  <joint name="left_HandFingerOneKnuckleThreeJoint" type="revolute">
    <parent link="left_HandFingerOneKnuckleTwoLink"/>
    <child link="left_HandFingerOneKnuckleThreeLink"/>
    <!-- 39.56 degrees -->
    <origin rpy="0 0 -0.690452252" xyz="0.07 0 0"/>
    <axis xyz="0 0 -1"/>
    <!-- measured max angle is 94.  so upper limit is 94 - start orientation (42 degrees)-->
    <limit effort="2" lower="0" upper="0.837733333" velocity="3.27"/>
    <dynamics damping="0.05"/>
  </joint>
  <gazebo reference="left_HandFingerOneKnuckleThreeJoint">
    <provideFeedback>true</provideFeedback>
  </gazebo>
  <link name="left_HandFingerTwoKnuckleOneLink">
    <visual>
      <origin rpy="1.57079632679 0 -1.57079632679" xyz="0 0 -0.0045"/>
      <geometry>
        <mesh filename="package://barrett_hand_defs/meshes/firstFingerLink.stl"/>
      </geometry>
      <material name="bh_HandGrey"/>
    </visual>
    <inertial>
      <origin xyz="0.03201666 -0.00086502 0.00890075"/>
      <mass value="0.16252678"/>
      <inertia ixx="0.00002567" ixy="-0.00000146" ixz="0.00001128" iyy="0.00008818" iyz="-0.00000094" izz="0.00007827"/>
    </inertial>
    <collision>
      <origin rpy="0 0 0" xyz="0.0270798802376 0 0.00195854902267"/>
      <geometry>
        <box size="0.0752255320549 0.0278776362538 0.0362581014633"/>
      </geometry>
    </collision>
    <collision>
      <origin rpy="0 0 0" xyz="0.0493242815137 0 0.0150546580553"/>
      <geometry>
        <sphere radius="0.0196040868759"/>
      </geometry>
    </collision>
  </link>
  <gazebo reference="left_HandFingerTwoKnuckleOneLink">
    <turnGravityOff>false</turnGravityOff>
    <selfCollide>true</selfCollide>
  </gazebo>
  <joint name="left_HandFingerTwoKnuckleOneJoint" type="revolute">
    <parent link="left_HandPalmLink"/>
    <child link="left_HandFingerTwoKnuckleOneLink"/>
    <origin rpy="0 0 1.57079632679" xyz="-0.02497 0 0.0587966"/>
    <axis xyz="0 0 1"/>
    <limit effort="2" lower="0" upper="3.14159265359" velocity="3.27"/>
    <dynamics damping="0.1"/>
  </joint>
  <gazebo reference="left_HandFingerTwoKnuckleOneJoint">
    <provideFeedback>true</provideFeedback>
  </gazebo>
  <link name="left_HandFingerTwoKnuckleTwoLink">
    <visual>
      <origin rpy="3.14159265359 1.57079632679 0" xyz="0 0 0"/>
      <geometry>
        <mesh filename="package://barrett_hand_defs/meshes/secondFingerLink.stl"/>
      </geometry>
      <material name="bh_HandGrey"/>
    </visual>
    <inertial>
      <origin xyz="0.031720 0.001070 -0.000586"/>
      <mass value="0.057957"/>
      <inertia ixx="0.00000461" ixy="0.00000003" ixz="0.00000164" iyy="0.00003590" iyz="0.00000004" izz="0.00003682"/>
    </inertial>
    <collision>
      <origin rpy="0 0 0.0424077153578" xyz="0.0455318503082 0 0"/>
      <geometry>
        <box size="0.0572708845139 0.0259905532002 0.0224001407623"/>
      </geometry>
    </collision>
    <self_collision_checking>
      <origin rpy="0 1.57075 0" xyz="0.03 0.0 0.0"/>
      <geometry>
        <capsule length="0.06" radius="0.015"/>
      </geometry>
    </self_collision_checking>
    <!--
      <self_collision_checking>
        <origin xyz="0.04 -0.01 0.0" rpy="0 1.57075 -0.5"/>
        <geometry>
          <capsule radius="0.01" length="0.1"/>
        </geometry>
      </self_collision_checking>
-->
  </link>
  <gazebo reference="left_HandFingerTwoKnuckleTwoLink">
    <turnGravityOff>false</turnGravityOff>
    <selfCollide>true</selfCollide>
  </gazebo>
  <joint name="left_HandFingerTwoKnuckleTwoJoint" type="revolute">
    <parent link="left_HandFingerTwoKnuckleOneLink"/>
    <child link="left_HandFingerTwoKnuckleTwoLink"/>
    <origin rpy="-1.57079632679 0 0" xyz="0.05 0 0.0166034"/>
    <axis xyz="0 0 -1"/>
    <!-- 122 degrees - start orientation of 0.4 degrees-->
    <limit effort="2" lower="0" upper="2.443388889" velocity="3.27"/>
    <dynamics damping="0.05"/>
  </joint>
  <gazebo reference="left_HandFingerTwoKnuckleTwoJoint">
    <provideFeedback>true</provideFeedback>
  </gazebo>
  <link name="left_HandFingerTwoKnuckleThreeLink">
    <visual>
      <origin rpy="0 0 0" xyz="0 0 0"/>
      <geometry>
        <mesh filename="package://barrett_hand_defs/meshes/thirdFingerLink.stl"/>
      </geometry>
      <material name="bh_HandGrey"/>
    </visual>
    <!--      <inertial>
        <origin xyz="0.01970974 0.00182016 0.00020041" />
        <mass value="0.03421781" />
        <inertia  ixx="0.00000287" ixy="0.00000091"  ixz="-0.00000007"
                                   iyy="0.00001329"  iyz="-0.00000002"
                                                     izz="0.00001214" />
      </inertial>
-->
    <inertial>
      <origin xyz="0.01970974 0.00182016 0.00020041"/>
      <mass value="0.03421781"/>
      <inertia ixx="0.00000461" ixy="0.00000003" ixz="0.00000164" iyy="0.00003590" iyz="0.00000004" izz="0.00003682"/>
    </inertial>
    <collision>
      <origin rpy="0 0 0" xyz="0.0220463573933 0 0"/>
      <geometry>
        <box size="0.0456312298775 0.0218328088522 0.0227420330048"/>
      </geometry>
    </collision>
    <collision>
      <origin rpy="0 0 0" xyz="0.046044960618 0.001 0"/>
      <geometry>
        <sphere radius="0.012090086937"/>
      </geometry>
    </collision>
    <self_collision_checking>
      <origin rpy="0 1.57075 0" xyz="0.025 0.0 0.0"/>
      <geometry>
        <capsule length="0.05" radius="0.015"/>
      </geometry>
    </self_collision_checking>
  </link>
  <gazebo reference="left_HandFingerTwoKnuckleThreeLink">
    <turnGravityOff>false</turnGravityOff>
    <selfCollide>true</selfCollide>
  </gazebo>
  <joint name="left_HandFingerTwoKnuckleThreeJoint" type="revolute">
    <parent link="left_HandFingerTwoKnuckleTwoLink"/>
    <child link="left_HandFingerTwoKnuckleThreeLink"/>
    <!-- 39.56 degrees -->
    <origin rpy="0 0 -0.690452252" xyz="0.07 0 0"/>
    <axis xyz="0 0 -1"/>
    <!-- measured max angle is 94.  so upper limit is 94 - start orientation (42 degrees)-->
    <limit effort="2" lower="0" upper="0.837733333" velocity="3.27"/>
    <dynamics damping="0.05"/>
  </joint>
  <gazebo reference="left_HandFingerTwoKnuckleThreeJoint">
    <provideFeedback>true</provideFeedback>
  </gazebo>
  <!-- <xacro:fingers prefix="${prefix}" parent="${prefix}_HandFingerTwoKnuckleOneLink" number="Two" xyz="0.05 0 0.0166034" rpy="-${0.5 * PI} -0.0429350996 0"/> -->
  <joint name="head_base_joint" type="fixed">
    <origin rpy="0.00040339 -0.0062724 -0.048944" xyz="0.0105 -0.001 1.3117"/>
    <parent link="torso_link0"/>
    <child link="head_base"/>
  </joint>
  <link name="head_base">
    <visual>
      <origin rpy="0 0 0" xyz="0 0 0.0"/>
      <geometry>
        <mesh filename="package://velma_description/meshes/head_base_simplified.STL"/>
      </geometry>
      <material name="torso_gray">
        <color rgba="0.5 0.5 0.5 1"/>
      </material>
    </visual>
    <collision>
      <origin rpy="0 0 0" xyz="0 0 0.0"/>
      <geometry>
        <mesh filename="package://velma_description/meshes/collision/head_base_collision.STL"/>
      </geometry>
    </collision>
    <inertial>
      <mass value="0.2"/>
      <origin rpy="0 0 0" xyz="0 0 0.0625"/>
      <inertia ixx="0.000520833333333" ixy="0" ixz="0" iyy="0.000520833333333" iyz="0" izz="0.000520833333333"/>
    </inertial>
  </link>
  <joint name="head_pan_motor_joint" type="fixed">
    <origin rpy="0 0 0" xyz="0 0 0.025"/>
    <parent link="head_base"/>
    <child link="head_pan_motor"/>
  </joint>
  <link name="head_pan_motor">
    <visual>
      <origin rpy="0 0 0" xyz="0 0 0"/>
      <geometry>
        <mesh filename="package://velma_description/meshes/head_pan_simplified.STL"/>
      </geometry>
      <material name="torso_gray">
        <color rgba="0.5 0.5 0.5 1"/>
      </material>
    </visual>
    <collision>
      <origin rpy="0 0 0" xyz="0 0 0.0308"/>
      <geometry>
        <box size="0.14 0.09 0.06"/>
      </geometry>
    </collision>
    <self_collision_checking>
      <origin rpy="0 0 0" xyz="0.0 0 0.04"/>
      <geometry>
        <capsule length="0.08" radius="0.07"/>
      </geometry>
    </self_collision_checking>
    <inertial>
      <mass value="0.2"/>
      <origin rpy="0 0 0" xyz="0 0 0.0625"/>
      <inertia ixx="0.000520833333333" ixy="0" ixz="0" iyy="0.000520833333333" iyz="0" izz="0.000520833333333"/>
    </inertial>
  </link>
  <!-- pan -->
  <joint name="head_pan_joint" type="revolute">
    <origin rpy="0 0 0" xyz="0 0 0.062"/>
    <axis xyz="0 0 1"/>
    <parent link="head_pan_motor"/>
    <child link="head_pan_link"/>
    <limit effort="100" lower="-1.57" upper="1.57" velocity="1.57"/>
    <dynamics damping="0.1"/>
  </joint>
  <link name="head_pan_link">
    <visual>
      <origin rpy="0 0 0" xyz="0 0 0"/>
      <geometry>
        <mesh filename="package://velma_description/meshes/head_tilt_simplified.STL"/>
      </geometry>
      <material name="torso_gray">
        <color rgba="0.5 0.5 0.5 1"/>
      </material>
    </visual>
    <collision>
      <origin rpy="0 0 0" xyz="0 -0.00921 0.04463"/>
      <geometry>
        <box size="0.08 0.08 0.08"/>
      </geometry>
    </collision>
    <inertial>
      <mass value="0.2"/>
      <origin rpy="0 0 0" xyz="0 0 0.0625"/>
      <inertia ixx="0.000520833333333" ixy="0" ixz="0" iyy="0.000520833333333" iyz="0" izz="0.000520833333333"/>
    </inertial>
  </link>
  <gazebo reference="head_pan_link">
    <turnGravityOff>false</turnGravityOff>
    <selfCollide>true</selfCollide>
  </gazebo>
  <!-- tilt -->
  <joint name="head_tilt_joint" type="revolute">
    <origin rpy="0 0 0" xyz="0 0 0.048"/>
    <axis xyz="0 1 0"/>
    <parent link="head_pan_link"/>
    <child link="head_tilt_link_dummy"/>
    <limit effort="100" lower="-1.57" upper="1.57" velocity="100"/>
    <dynamics damping="0.1"/>
  </joint>
  <!-- PATCH: The added dummy joint and link is a bugfix for KDL issue with rotated joints -->
  <link name="head_tilt_link_dummy"/>
  <joint name="head_tilt_joint_dummy" type="fixed">
    <origin rpy="1.57079632679 0 0" xyz="0 0 0.0"/>
    <parent link="head_tilt_link_dummy"/>
    <child link="head_tilt_link"/>
    <limit effort="100" lower="-1.57" upper="1.57" velocity="100"/>
    <dynamics damping="0.1"/>
  </joint>
  <!-- end of PATCH -->
  <link name="head_tilt_link">
    <visual>
      <origin rpy="0 0 0" xyz="0 0 0.04219"/>
      <geometry>
        <mesh filename="package://velma_description/meshes/head_top_simplified.STL"/>
      </geometry>
      <material name="torso_gray">
        <color rgba="0.5 0.5 0.5 1"/>
      </material>
    </visual>
    <visual>
      <origin rpy="0 0 0 " xyz="0 0 0.04219"/>
      <geometry>
        <mesh filename="package://velma_description/meshes/collision/head_top_collision.STL"/>
      </geometry>
    </visual>
    <collision>
      <origin rpy="0 0 0 " xyz="0 0 0.04219"/>
      <geometry>
        <mesh filename="package://velma_description/meshes/collision/head_top_collision.STL"/>
      </geometry>
    </collision>
    <self_collision_checking>
      <origin rpy="-1.57075 0 0" xyz="0.0 0.12 0.0"/>
      <geometry>
        <capsule length="0.24" radius="0.07"/>
      </geometry>
    </self_collision_checking>
    <self_collision_checking>
      <origin rpy="-1.57075 0 0" xyz="-0.12 0.17 0.0"/>
      <geometry>
        <capsule length="0.14" radius="0.07"/>
      </geometry>
    </self_collision_checking>
    <self_collision_checking>
      <origin rpy="0 0 0" xyz="0.0 0.20 0.0"/>
      <geometry>
        <capsule length="0.23" radius="0.07"/>
      </geometry>
    </self_collision_checking>
    <inertial>
      <mass value="0.2"/>
      <origin rpy="0 0 0" xyz="0 0 0.0625"/>
      <inertia ixx="0.000520833333333" ixy="0" ixz="0" iyy="0.000520833333333" iyz="0" izz="0.000520833333333"/>
    </inertial>
  </link>
  <gazebo reference="head_tilt_link">
    <turnGravityOff>false</turnGravityOff>
    <selfCollide>true</selfCollide>
  </gazebo>
  <!-- sensors -->
  <!-- sensor physical attachment -->
  <joint name="stereo_left_joint" type="fixed">
    <origin rpy="-1.57287072792 0.00651187846263 -0.0625201582561" xyz="0.04272367283 0.2263882065 -0.04506107579"/>
    <parent link="head_tilt_link"/>
    <child link="stereo_left_link"/>
  </joint>
  <link name="stereo_left_link"/>
  <!-- sensor frame -->
  <joint name="stereo_left_optical_frame_joint" type="fixed">
    <origin rpy="-1.57 0.0 -1.57" xyz="0 0 0"/>
    <parent link="stereo_left_link"/>
    <child link="stereo_left_optical_frame"/>
  </joint>
  <link name="stereo_left_optical_frame"/>
  <!-- sensor physical attachment -->
  <joint name="stereo_right_joint" type="fixed">
    <origin rpy="-0.0011009 0.016076 0.0072743" xyz="0.0039764 -0.090444 -0.00065625"/>
    <parent link="stereo_left_link"/>
    <child link="stereo_right_link"/>
  </joint>
  <link name="stereo_right_link"/>
  <!-- sensor frame -->
  <joint name="stereo_right_optical_frame_joint" type="fixed">
    <origin rpy="-1.57 0.0 -1.57" xyz="0 0 0"/>
    <parent link="stereo_right_link"/>
    <child link="stereo_right_optical_frame"/>
  </joint>
  <link name="stereo_right_optical_frame"/>
  <!-- sensor physical attachment -->
  <joint name="head_kinect_rgb_joint" type="fixed">
    <origin rpy="-1.5527 0.015593 -0.094166" xyz="0.062644 0.19458 0.017223"/>
    <parent link="head_tilt_link"/>
    <child link="head_kinect_rgb_link"/>
  </joint>
  <link name="head_kinect_rgb_link"/>
  <!-- sensor frame -->
  <joint name="head_kinect_rgb_optical_frame_joint" type="fixed">
    <origin rpy="-1.57 0.0 -1.57" xyz="0 0 0"/>
    <parent link="head_kinect_rgb_link"/>
    <child link="head_kinect_rgb_optical_frame"/>
  </joint>
  <link name="head_kinect_rgb_optical_frame"/>
</robot>

